Workbook

Sheet 트래블마트 통합
A1: 2026 Travel Mart Schedule + Super Event (트래블마트 캘린더 통합) | N1: Update: 2026-7-30
A2: 국가 | B2: 도시 | C2: 2026년 1월 | D2: 2026년 2월 | E2: 2026년 3월 | F2: 2026년 4월 | G2: 2026년 5월 | H2: 2026년 6월 | I2: 2026년 7월 | J2: 2026년 8월 | K2: 2026년 9월 | L2: 2026년 10월 | M2: 2026년 11월 | N2: 2026년 12월 | O2: 2027년 1월 | P2: 2027년 2월 | Q2: 2027년 3월 | R2: 2027년 4월 | S2: 2027년 5월 | T2: 2027년 6월
A3: Super Events (Sports) | D3: 2026 밀라노-코르티나 동계올림픽 (이탈리아) 2026년 2월 6일 ~ 2월 22일 | E3: Grand Prix 13-15 March 2026 상하이 27-29 March 2026 일본 | F3: Grand Prix 10-12 April 2026 바레인 17-19 April 2026 사우디 | H3: 2026 FIFA 월드컵 (미국·캐나다·멕시코) 2026년 6월 11일 ~ 7월 19일 | J3: 2026 커먼웰스 게임즈 (조호르, 말레이시아 예정) | L3: Grand Prix 9-11 October 2026 싱가포르 | N3: Grand Prix 4-6 December 2026 UAE | Q3: F1 Grand Prix 중국(상하이)·일본(스즈카) 3월 중 (예상) | T3: 2027 FIFA 여자월드컵 (브라질) 2027년 6월 24일 ~ 7월 25일
A4: Super Events (Religious & Culture) | D4: 라마단 & 이드 알 피트르 라마단: 2026년 2월 20일 ~ 3월 21일 이드: 2026년 3월 22일 중동 → 동남아 (태국·말레이시아·한국) 여행 붐 | F4: 골든위크(일본) 2026년 4월 29일 ~ 5월 5일 Qingming Festival (청명절) 중국·홍콩·대만 출발 단기 여행 증가 | G4: Wesak (부처님오신날) 인도네시아·태국·말레이시아·싱가포르 | K4: 추석 한국·중국 outbound 혼잡 일본·베트남·대만 호텔 추가 수요 발생 | M4: Diwali (빛의 축제) – 인도 및 인도계 디아스포라 인도 출발 아웃바운드 여행 증가 → 태국, 베트남, 아랍에미리트 Yi Peng Festival (라이트·랜턴 축제) - 태국 | P4: 라마단 & 이드 알 피트르 라마단: 2027년 2월 9일경 ~ 3월 10일경 (예상) 이드: 3월 11일경 중동 → 동남아·한국 여행 붐 | Q4: 이드 알 피트르 3월 11일경 (예상) 중동·인도네시아·말레이시아 장기 연휴 | R4: 골든위크(일본) 4월 29일 ~ 5월 5일 Qingming Festival (청명절) 4월 5일 중국·홍콩·대만 단기 여행 증가 | S4: Wesak (부처님오신날) 5월 중 인도네시아·태국·말레이시아·싱가포르
A5: Super Events (MICE) | C5: CES 2026 (라스베가스) | D5: MWC Barcelona 2026 | E5: GDC(San Francisco), SXSW(Austin) | F5: China Import & Export Fair | K5: ASEAN Summit 2026 — 라오스 (Vientiane) 개최 | L5: China Import & Export Fair Japan CEATEC – 일본 최대 ICT 박람회 | M5: Web Summit 2026 (리스본) APEC Summit 2026 – 싱가포르 Singapore FinTech Festival 2026 Seoul MICE Week | O5: CES 2027 (라스베이거스) 1월 상순 (예상) | Q5: MWC Barcelona 2027 (3월 상순, 예상) SXSW Austin / GDC San Francisco (3월) | R5: China Import & Export Fair (캔톤페어) 4월 중순 ~ 5월 초
A6: China Events | C6: 방학시즌 | D6: 춘절 | F6: 벗꽃축제 | G6: 국경절, 노동절 | J6: 방학시즌 | K6: 추석, 중추절 | N6: 방학시즌 | O6: 방학시즌 | P6: 춘절 (2027년 2월 6일) | R6: 벚꽃축제 | S6: 노동절 (5/1~5/5)
A7: SEA Events | D7: Chiness New Year | P7: Chinese New Year (2/6)
A8: India & Rusia
A9: 중국 | B9: 광동,화동,화북,내륙 | C9: 1차 세일즈콜 광저우, 심천 | D9: Chiness New Year | E9: 1차 세일즈 콜 베이징 | F9: 1차 세일즈 콜 청두, 시안, 중경 COTTM Beijing (보통 4월) [★★★ 최우선] 중국 outbound 전문 B2B | G9: 5/26–5/28 – ITB China 1차 Shanghai GITF (Guangzhou International Travel Fair) 5/21–23 [★★★ 최우선] 중국 outbound 최상위 B2B | I9: 2차 세일즈 콜 심천+대만+홍콩 | K9: 2차 광저우, 심천 | L9: 1차 세일즈 콜 청두, 시안, 무한 CITIE Tourism Expo 2026 Guangzhou China (September 11-13) 2026 CHINA OUTBOUND & INBOUND TRAVEL MARKET 10/14–16 (베이징) | M9: 2차 베이징 국경절 1~7일 COITM from 14-16 October in Beijing | N9: 2차 상하이 | P9: Chinese New Year (2/6) | R9: COTTM Beijing 2027 4월 중 (예상) [★★★ 최우선] 중국 outbound 전문 B2B | S9: ITB China 2027 (상하이) 5월 중 (예상) GITF Guangzhou 5월 하순 (예상) [★★★ 최우선] 중국 outbound 최상위 B2B
A10: 한국 | B10: 서울 | G10: 일산 트래블마트 5월 14~17일 | H10: 6/4–6/7 – Seoul International Travel Fair (SITF) [★ 선택] 한국 최대 여행박람회 | I10: 6/30~7/1 SITM | J10: 한국 세일즈콜 8월3~7일 | M10: Travel Show 11월 12~15일 Korea MICE Expo (KME) 11/18–11/20 [★ 선택] 한국 MICE 대표 행사 | S10: 일산 트래블마트 2027 5월 중 (예상) | T10: Seoul International Travel Fair (SITF) 2027 6월 상순 (예상) SITM 6월 말~7월 초 (예상) [★ 선택] 한국 최대 여행박람회
A11: 일본 | B11: (순환개최) | K11: 9/24–9/27 – Tourism EXPO Japan (TEJ) [★★ 중간] 일본 최대 종합 트래블쇼
A12: 대만 | B12: 타이베이 | C12: 1차 세일즈 콜 대만+홍콩 | G12: 5/22–5/25 – Taipei Tourism Expo (TTE) [★ 선택] 대만 최대 B2C, FIT 시장 강함 | I12: 2차 세일즈 콜 심천+대만+홍콩 | M12: ITF Taiwan International Travel Fair (ITF) 11월 6일 (금) ~ 11월 9일(월) | S12: Taipei Tourism Expo (TTE) 2027 5월 하순 (예상) [★ 선택] 대만 최대 B2C, FIT 시장 강함
A13: 홍콩 | B13: 홍콩 | C13: 1차 세일즈 콜 대만+홍콩 | H13: ITE Hong Kong 6월 11~14일 전후 [★★ 중간] 홍콩–광둥 outbound 중심 | I13: 2차 세일즈 콜 심천+대만+홍콩 | K13: 2차 세일즈 콜 대만+홍콩 | T13: ITE Hong Kong 2027 6월 중순 (예상) [★★ 중간] 홍콩–광둥 outbound 중심
A14: 필리핀 | B14: 세부, 마닐라 | C14: 1/28–1/30 – ASEAN Tourism Forum + TRAVEX [★★ 중간] ASEAN 10개국 공식 B2B, 관광청 네트워크 최강 | D14: 2/6–2/8 – PTAA TravelTour Expo [★★★ 최우선] 필리핀 최대 소비자+B2B, 패키지 판매에 최적 | I14: Travel Madness Expo 2026 July 10 to 12, 2026 | O14: ASEAN Tourism Forum + TRAVEX 2027 1월 하순 (예상, 개최국 순회) [★★ 중간] ASEAN 10개국 공식 B2B, 관광청 네트워킹 | P14: PTAA TravelTour Expo 2027 2월 중 (예상) [★★★ 최우선] 필리핀 최대 소비자+B2B, 패키지 판매에 최적
A15: 베트남 | B15: 호치민 하노이 | F15: Vietnam International Travel Mart HANOI [★★ 중간] 북베트남 B2B+B2C | L15: ITE HCMC 16~18 Oct [★★ 중간] 메콩 최대 B2B+B2C (Calendar 기준 9/3–9/5) | R15: VITM Hanoi 2027 (Vietnam Int'l Travel Mart) 4월 상순 (예상) [★★ 중간] 북베트남 B2B+B2C
A16: 태국 | B16: 방콕 | C16: 1/22–1/25 – Thai International Travel Fair [★★★ 최우선] 태국 최대 B2B+B2C, 태국→한국·일본 outbound 중심 | E16: 5-8 Mar Thai Teaw Thai (77th Edition) B2C | H16: TTM+ (Thailand Travel Mart Plus) 2026 예상 날짜: 2026년 6월 중 (보통 6월 둘째 주) 장소: 미정 특징: 태국 관광청(TAT) 주관 행사 | L16: Visit Japan FIT Fair #17 올해 10월16~18일 개최 | O16: Thai International Travel Fair 2027 1월 하순 (예상) [★★★ 최우선] 태국 최대 B2B+B2C | Q16: Thai Teaw Thai (B2C) 3월 상순 (예상) | T16: TTM+ (Thailand Travel Mart Plus) 2027 6월 둘째 주 (예상) 태국 관광청(TAT) 주관
A17: 말레이시아 | B17: 쿠알라룸프르, 쿠칭 | E17: MATTA Fair 3 - 5 April 2026 [★ 선택] 말레이시아 최대 B2C | J17: 8/18–8/20 – PATA Travel Mart [★★ 중간] 아시아·태평양 대표 B2B | K17: MATTA Fair [★ 선택] 말레이시아 최대 B2C | Q17: MATTA Fair 2027 (상반기) 3월 말~4월 초 (예상) [★ 선택] 말레이시아 최대 B2C
A18: 싱가포르 | B18: 마리나베이 | H18: ILTM Asia Pacific 2026 2026년 6월 29일 ~ 7월 2일 [★ 선택] 아시아 럭셔리 여행 최상위 행사 | J18: NATAS (2026년 8월 21~23일) | L18: 10/21–10/23 – ITB Asia [★★★ 최우선] 아시아 No.1 B2B 허브 | T18: ILTM Asia Pacific 2027 (싱가포르) 6월 말 (예상) [★ 선택] 아시아 럭셔리 여행 최상위 행사
A19: 인도네시아 | B19: 자카르타 | G19: BBTF (Bali & Beyond Travel Fair) 2026 날짜: 2026년 5월 28일(목) ~ 5월 30일(토) 특징: 상반기 동남아시아 일정 중 호텔 소싱에 가장 중요한 행사 | H19: Travel Meet Asia 2026 2026년 6월 23-24일 [★ 선택] 아세안 B2B 네트워크 허브 | T19: BBTF (Bali & Beyond Travel Fair) 2027 6월 중 (예상) Travel Meet Asia 2027 6월 하순 (예상) 호텔 소싱 핵심 행사
A20: 인도 | B20: 뭄바이 뉴델리 | C20: OTM (Outbound Travel Mart, Mumbai) 5-7 Feb | D20: SATTE 2026 2026.02.25 – 02.27 [★★ 중간] 남아시아 인바운드/아웃바운드 | K20: 9/2–9/4 – ITB India [★★★ 최우선] 인도 outbound 핵심 | L20: South Asia Travel & Tourism Exchange | P20: OTM Mumbai 2027 (Outbound Travel Mart) 2월 상순 (예상) SATTE 2027 (뉴델리) 2월 하순 (예상) [★★ 중간] 인도 아웃바운드 핵심
A21: 러시아 | B21: 모스크바 | E21: MITT 2026 2026년 3월 11일 ~ 3월 13일 [★★ 중간] 러시아·CIS 최대, 러시아 outbound 핵심 | K21: OTDYKH Leisure Travel Market 2026 2026년 9월 10일 ~ 9월 12일 [★ 선택] 러시아 인바운드·아웃바운드 모두 강함 | Q21: MITT Moscow 2027 3월 중 (예상) [★★ 중간] 러시아·CIS 최대, 러시아 outbound 핵심
A22: UAE | B22: Dubai | G22: Arabian Travel Market (ATM) 2026 2026년 5월 4일 ~ 5월 7일 [★★★ 최우선] 중동 최대 여행 B2B, GCC 바이어 중심 | S22: Arabian Travel Market (ATM) 2027 (Dubai) 5월 상순 (예상) [★★★ 최우선] 중동 최대 여행 B2B, GCC 바이어 중심
A23: Qatar | B23: Doha | E23: Connections Luxury Middle East 2026 2026년 3월 29일 ~ 4월 1일 [★ 선택] 초럭셔리 바이어 행사, 하이엔드 전략용 | Q23: Connections Luxury Middle East 2027 3월 말~4월 초 (예상) [★ 선택] 초럭셔리 바이어 행사
A24: 독일 | B24: 베를린 오버하우젠 | E24: ITB Berlin 2026 2026년 3월 3일(화) ~ 3월 5일(목) [★★★ 최우선] 세계 1위 여행 B2B, 글로벌 파트너 확장 필수 | F24: Germany Travel Mart (GTM) 2026 2026년 4월 19일 ~ 21일 [★ 선택] 독일 관광청 주최, 유럽 인바운드 중심 | Q24: ITB Berlin 2027 3월 상순 (예상, 통상 첫째 주 화~목) [★★★ 최우선] 세계 1위 여행 B2B, 글로벌 파트너 확장 필수 | R24: Germany Travel Mart (GTM) 2027 4월 중 (예상) [★ 선택] 독일 관광청 주최, 유럽 인바운드 중심
A25: 호주 | B25: 시드니, 애들레이드 | G25: 5/10–5/14 – Australian Tourism Exchange (ATE) [★ 선택] 오세아니아 최대 B2B | L25: Luxperience | S25: Australian Tourism Exchange (ATE) 2027 5월 중 (예상) [★ 선택] 오세아니아 최대 B2B
A26: 영국 | B26: 런던 | M26: WTM London 2026 2026.11.04 – 11.06 [★★★ 최우선] 글로벌 레저, 기술, 지속가능성
A27: 스페인 | B27: 마드리드 | C27: FITUR Madrid 2026 1월 21일 ~ 25일 [★★ 중간] 세계 3대 관광박람회, 유럽·라틴 시장 핵심 B2B | O27: FITUR Madrid 2027 1월 하순 (예상, 통상 1/20~1/24) [★★ 중간] 세계 3대 관광박람회, 유럽·라틴 핵심
A28: 미국 | B28: 플로리다주 뉴욕 | C28: NYTTravel Show | D28: NYTTravel Show | E28: NYTTravel Show | F28: NYTTravel Show | G28: IPW 2026 2026년 5월 17-21일 [★ 선택] 미국 인바운드 최대 B2B 행사 | L28: Business Travel Show America 2026 2026년 10월 14-15일 [★ 선택] 북미 코퍼레이트 트래블 대표 행사 | O28: New York Times Travel Show 2027 1월 하순 (예상) | S28: IPW 2027 (U.S. Travel Association) 5월 하순 (예상) [★ 선택] 미국 인바운드 최대 B2B
A29: 멕시코 | B29: 과달라하라 | M29: ITB Americas 2026 2026년 11월 10-12일 [★ 선택] 미주 전역 바이어 연결 허브
A30: South Africa | B30: Cape Town | F30: WTM Africa 2026 [★ 선택] 아프리카 시장 접근 | R30: WTM Africa 2027 (Cape Town) 4월 중 (예상) [★ 선택] 아프리카 시장 접근
A31: 브라질 | B31: 상파울루 | F31: WTM Latin America 2026 2026년 4월 14-16일 [★ 선택] 남미 최대 B2B, 라틴 바이어 네트워크 | R31: WTM Latin America 2027 (상파울루) 4월 중 (예상) [★ 선택] 남미 최대 B2B, 라틴 바이어 네트워크
A33: 범례 (우선순위 · FOR OMH BY AI)
A34: ★★★ 최우선 | B34: 반드시 참가 · 핵심 소싱/바이어 시장 (셀 좌측 굵은 파란선)
A35: ★★ 중간 | B35: 여력에 따라 참가 · 지역 보완용 (좌측 검정선)
A36: ★ 선택 | B36: 선택 참가 · 전략적 필요 시 (좌측 빨간선)
A37: 비고 | B37: 각 행사 셀 하단의 [우선순위] 표기와 설명은 기존 Calendar 시트에서 통합된 내용입니다. ITE HCMC는 두 자료의 일정이 상이(10/16–18 vs 9/3–5)하여 병기했습니다.
A38: ※ 2027년 상반기(O~T열) 일정은 매년 정기 개최되는 행사를 기준으로 작성한 초안입니다. "(예상)"으로 표기된 일정은 주최 측 공식 발표 전이므로 확정 시 업데이트가 필요합니다. (웹 검색 차단 상태에서 작성 · 2026-08-18)

Sheet 일정 체크리스트
A1: 2026 트래블마트 일정 체크리스트 (2027년 상반기 포함) | E1: 참가 | F1: =COUNTIF(F4:F95,TRUE)&" / "&COUNTA(D4:D95) -> 30 / 92 | G1: 진행완료 | H1: =COUNTIF(G4:G95,TRUE)&" / "&COUNTA(D4:D95) -> 20 / 92
A3: 월 | B3: 국가 | C3: 도시 | D3: 일정명 | E3: 우선순위 | F3: 참가 | G3: 진행완료 | H3: 상태 | I3: 상세 내용 | J3: 비고
A4: ='트래블마트 통합'!C$2 -> 2026년 1월 | B4: ='트래블마트 통합'!$A9 -> 중국 | C4: ='트래블마트 통합'!$B9 -> 광동,화동,화북,내륙 | D4: =IFERROR(LEFT('트래블마트 통합'!C9,FIND(CHAR(10),'트래블마트 통합'!C9)-1),'트래블마트 통합'!C9) -> 1차 세일즈콜 | E4: =IF(ISNUMBER(SEARCH("★★★",'트래블마트 통합'!C9)),"★★★",IF(ISNUMBER(SEARCH("★★",'트래블마트 통합'!C9)),"★★",IF(ISNUMBER(SEARCH("★",'트래블마트 통합'!C9)),"★","-"))) -> - | F4: TRUE | G4: TRUE | H4: =IF(AND(F4,G4),"완료",IF(G4,"진행 완료",IF(F4,"참가 예정","미정"))) -> 완료 | I4: ='트래블마트 통합'!C9 -> 1차 세일즈콜 광저우, 심천
A5: ='트래블마트 통합'!C$2 -> 2026년 1월 | B5: ='트래블마트 통합'!$A12 -> 대만 | C5: ='트래블마트 통합'!$B12 -> 타이베이 | D5: =IFERROR(LEFT('트래블마트 통합'!C12,FIND(CHAR(10),'트래블마트 통합'!C12)-1),'트래블마트 통합'!C12) -> 1차 세일즈 콜 | E5: =IF(ISNUMBER(SEARCH("★★★",'트래블마트 통합'!C12)),"★★★",IF(ISNUMBER(SEARCH("★★",'트래블마트 통합'!C12)),"★★",IF(ISNUMBER(SEARCH("★",'트래블마트 통합'!C12)),"★","-"))) -> - | F5: TRUE | G5: TRUE | H5: =IF(AND(F5,G5),"완료",IF(G5,"진행 완료",IF(F5,"참가 예정","미정"))) -> 완료 | I5: ='트래블마트 통합'!C12 -> 1차 세일즈 콜 대만+홍콩
A6: ='트래블마트 통합'!C$2 -> 2026년 1월 | B6: ='트래블마트 통합'!$A13 -> 홍콩 | C6: ='트래블마트 통합'!$B13 -> 홍콩 | D6: =IFERROR(LEFT('트래블마트 통합'!C13,FIND(CHAR(10),'트래블마트 통합'!C13)-1),'트래블마트 통합'!C13) -> 1차 세일즈 콜 | E6: =IF(ISNUMBER(SEARCH("★★★",'트래블마트 통합'!C13)),"★★★",IF(ISNUMBER(SEARCH("★★",'트래블마트 통합'!C13)),"★★",IF(ISNUMBER(SEARCH("★",'트래블마트 통합'!C13)),"★","-"))) -> - | F6: TRUE | G6: TRUE | H6: =IF(AND(F6,G6),"완료",IF(G6,"진행 완료",IF(F6,"참가 예정","미정"))) -> 완료 | I6: ='트래블마트 통합'!C13 -> 1차 세일즈 콜 대만+홍콩
A7: ='트래블마트 통합'!C$2 -> 2026년 1월 | B7: ='트래블마트 통합'!$A14 -> 필리핀 | C7: ='트래블마트 통합'!$B14 -> 세부, 마닐라 | D7: =IFERROR(LEFT('트래블마트 통합'!C14,FIND(CHAR(10),'트래블마트 통합'!C14)-1),'트래블마트 통합'!C14) -> 1/28–1/30 – ASEAN Tourism Forum + TRAVEX | E7: =IF(ISNUMBER(SEARCH("★★★",'트래블마트 통합'!C14)),"★★★",IF(ISNUMBER(SEARCH("★★",'트래블마트 통합'!C14)),"★★",IF(ISNUMBER(SEARCH("★",'트래블마트 통합'!C14)),"★","-"))) -> ★★ | F7: TRUE | G7: TRUE | H7: =IF(AND(F7,G7),"완료",IF(G7,"진행 완료",IF(F7,"참가 예정","미정"))) -> 완료 | I7: ='트래블마트 통합'!C14 -> 1/28–1/30 – ASEAN Tourism Forum + TRAVEX [★★ 중간] ASEAN 10개국 공식 B2B, 관광청 네트워크 최강
A8: ='트래블마트 통합'!C$2 -> 2026년 1월 | B8: ='트래블마트 통합'!$A16 -> 태국 | C8: ='트래블마트 통합'!$B16 -> 방콕 | D8: =IFERROR(LEFT('트래블마트 통합'!C16,FIND(CHAR(10),'트래블마트 통합'!C16)-1),'트래블마트 통합'!C16) -> 1/22–1/25 – Thai International Travel Fair | E8: =IF(ISNUMBER(SEARCH("★★★",'트래블마트 통합'!C16)),"★★★",IF(ISNUMBER(SEARCH("★★",'트래블마트 통합'!C16)),"★★",IF(ISNUMBER(SEARCH("★",'트래블마트 통합'!C16)),"★","-"))) -> ★★★ | F8: TRUE | G8: TRUE | H8: =IF(AND(F8,G8),"완료",IF(G8,"진행 완료",IF(F8,"참가 예정","미정"))) -> 완료 | I8: ='트래블마트 통합'!C16 -> 1/22–1/25 – Thai International Travel Fair [★★★ 최우선] 태국 최대 B2B+B2C, 태국→한국·일본 outbound 중심
A9: ='트래블마트 통합'!C$2 -> 2026년 1월 | B9: ='트래블마트 통합'!$A20 -> 인도 | C9: ='트래블마트 통합'!$B20 -> 뭄바이 뉴델리 | D9: =IFERROR(LEFT('트래블마트 통합'!C20,FIND(CHAR(10),'트래블마트 통합'!C20)-1),'트래블마트 통합'!C20) -> OTM (Outbound Travel Mart, Mumbai) | E9: =IF(ISNUMBER(SEARCH("★★★",'트래블마트 통합'!C20)),"★★★",IF(ISNUMBER(SEARCH("★★",'트래블마트 통합'!C20)),"★★",IF(ISNUMBER(SEARCH("★",'트래블마트 통합'!C20)),"★","-"))) -> - | F9: TRUE | G9: TRUE | H9: =IF(AND(F9,G9),"완료",IF(G9,"진행 완료",IF(F9,"참가 예정","미정"))) -> 완료 | I9: ='트래블마트 통합'!C20 -> OTM (Outbound Travel Mart, Mumbai) 5-7 Feb
A10: ='트래블마트 통합'!C$2 -> 2026년 1월 | B10: ='트래블마트 통합'!$A27 -> 스페인 | C10: ='트래블마트 통합'!$B27 -> 마드리드 | D10: =IFERROR(LEFT('트래블마트 통합'!C27,FIND(CHAR(10),'트래블마트 통합'!C27)-1),'트래블마트 통합'!C27) -> FITUR Madrid 2026 | E10: =IF(ISNUMBER(SEARCH("★★★",'트래블마트 통합'!C27)),"★★★",IF(ISNUMBER(SEARCH("★★",'트래블마트 통합'!C27)),"★★",IF(ISNUMBER(SEARCH("★",'트래블마트 통합'!C27)),"★","-"))) -> ★★ | F10: FALSE | G10: FALSE | H10: =IF(AND(F10,G10),"완료",IF(G10,"진행 완료",IF(F10,"참가 예정","미정"))) -> 미정 | I10: ='트래블마트 통합'!C27 -> FITUR Madrid 2026 1월 21일 ~ 25일 [★★ 중간] 세계 3대 관광박람회, 유럽·라틴 시장 핵심 B2B
A11: ='트래블마트 통합'!C$2 -> 2026년 1월 | B11: ='트래블마트 통합'!$A28 -> 미국 | C11: ='트래블마트 통합'!$B28 -> 플로리다주 뉴욕 | D11: =IFERROR(LEFT('트래블마트 통합'!C28,FIND(CHAR(10),'트래블마트 통합'!C28)-1),'트래블마트 통합'!C28) -> NYTTravel Show | E11: =IF(ISNUMBER(SEARCH("★★★",'트래블마트 통합'!C28)),"★★★",IF(ISNUMBER(SEARCH("★★",'트래블마트 통합'!C28)),"★★",IF(ISNUMBER(SEARCH("★",'트래블마트 통합'!C28)),"★","-"))) -> - | F11: FALSE | G11: FALSE | H11: =IF(AND(F11,G11),"완료",IF(G11,"진행 완료",IF(F11,"참가 예정","미정"))) -> 미정 | I11: ='트래블마트 통합'!C28 -> NYTTravel Show
A12: ='트래블마트 통합'!D$2 -> 2026년 2월 | B12: ='트래블마트 통합'!$A9 -> 중국 | C12: ='트래블마트 통합'!$B9 -> 광동,화동,화북,내륙 | D12: =IFERROR(LEFT('트래블마트 통합'!D9,FIND(CHAR(10),'트래블마트 통합'!D9)-1),'트래블마트 통합'!D9) -> Chiness New Year | E12: =IF(ISNUMBER(SEARCH("★★★",'트래블마트 통합'!D9)),"★★★",IF(ISNUMBER(SEARCH("★★",'트래블마트 통합'!D9)),"★★",IF(ISNUMBER(SEARCH("★",'트래블마트 통합'!D9)),"★","-"))) -> - | F12: TRUE | G12: TRUE | H12: =IF(AND(F12,G12),"완료",IF(G12,"진행 완료",IF(F12,"참가 예정","미정"))) -> 완료 | I12: ='트래블마트 통합'!D9 -> Chiness New Year
A13: ='트래블마트 통합'!D$2 -> 2026년 2월 | B13: ='트래블마트 통합'!$A14 -> 필리핀 | C13: ='트래블마트 통합'!$B14 -> 세부, 마닐라 | D13: =IFERROR(LEFT('트래블마트 통합'!D14,FIND(CHAR(10),'트래블마트 통합'!D14)-1),'트래블마트 통합'!D14) -> 2/6–2/8 – PTAA TravelTour Expo | E13: =IF(ISNUMBER(SEARCH("★★★",'트래블마트 통합'!D14)),"★★★",IF(ISNUMBER(SEARCH("★★",'트래블마트 통합'!D14)),"★★",IF(ISNUMBER(SEARCH("★",'트래블마트 통합'!D14)),"★","-"))) -> ★★★ | F13: FALSE | G13: FALSE | H13: =IF(AND(F13,G13),"완료",IF(G13,"진행 완료",IF(F13,"참가 예정","미정"))) -> 미정 | I13: ='트래블마트 통합'!D14 -> 2/6–2/8 – PTAA TravelTour Expo [★★★ 최우선] 필리핀 최대 소비자+B2B, 패키지 판매에 최적
A14: ='트래블마트 통합'!D$2 -> 2026년 2월 | B14: ='트래블마트 통합'!$A20 -> 인도 | C14: ='트래블마트 통합'!$B20 -> 뭄바이 뉴델리 | D14: =IFERROR(LEFT('트래블마트 통합'!D20,FIND(CHAR(10),'트래블마트 통합'!D20)-1),'트래블마트 통합'!D20) -> SATTE 2026 | E14: =IF(ISNUMBER(SEARCH("★★★",'트래블마트 통합'!D20)),"★★★",IF(ISNUMBER(SEARCH("★★",'트래블마트 통합'!D20)),"★★",IF(ISNUMBER(SEARCH("★",'트래블마트 통합'!D20)),"★","-"))) -> ★★ | F14: TRUE | G14: TRUE | H14: =IF(AND(F14,G14),"완료",IF(G14,"진행 완료",IF(F14,"참가 예정","미정"))) -> 완료 | I14: ='트래블마트 통합'!D20 -> SATTE 2026 2026.02.25 – 02.27 [★★ 중간] 남아시아 인바운드/아웃바운드
A15: ='트래블마트 통합'!D$2 -> 2026년 2월 | B15: ='트래블마트 통합'!$A28 -> 미국 | C15: ='트래블마트 통합'!$B28 -> 플로리다주 뉴욕 | D15: =IFERROR(LEFT('트래블마트 통합'!D28,FIND(CHAR(10),'트래블마트 통합'!D28)-1),'트래블마트 통합'!D28) -> NYTTravel Show | E15: =IF(ISNUMBER(SEARCH("★★★",'트래블마트 통합'!D28)),"★★★",IF(ISNUMBER(SEARCH("★★",'트래블마트 통합'!D28)),"★★",IF(ISNUMBER(SEARCH("★",'트래블마트 통합'!D28)),"★","-"))) -> - | F15: FALSE | G15: FALSE | H15: =IF(AND(F15,G15),"완료",IF(G15,"진행 완료",IF(F15,"참가 예정","미정"))) -> 미정 | I15: ='트래블마트 통합'!D28 -> NYTTravel Show
A16: ='트래블마트 통합'!E$2 -> 2026년 3월 | B16: ='트래블마트 통합'!$A9 -> 중국 | C16: ='트래블마트 통합'!$B9 -> 광동,화동,화북,내륙 | D16: =IFERROR(LEFT('트래블마트 통합'!E9,FIND(CHAR(10),'트래블마트 통합'!E9)-1),'트래블마트 통합'!E9) -> 1차 세일즈 콜 | E16: =IF(ISNUMBER(SEARCH("★★★",'트래블마트 통합'!E9)),"★★★",IF(ISNUMBER(SEARCH("★★",'트래블마트 통합'!E9)),"★★",IF(ISNUMBER(SEARCH("★",'트래블마트 통합'!E9)),"★","-"))) -> - | F16: TRUE | G16: TRUE | H16: =IF(AND(F16,G16),"완료",IF(G16,"진행 완료",IF(F16,"참가 예정","미정"))) -> 완료 | I16: ='트래블마트 통합'!E9 -> 1차 세일즈 콜 베이징
A17: ='트래블마트 통합'!E$2 -> 2026년 3월 | B17: ='트래블마트 통합'!$A16 -> 태국 | C17: ='트래블마트 통합'!$B16 -> 방콕 | D17: =IFERROR(LEFT('트래블마트 통합'!E16,FIND(CHAR(10),'트래블마트 통합'!E16)-1),'트래블마트 통합'!E16) -> 5-8 Mar | E17: =IF(ISNUMBER(SEARCH("★★★",'트래블마트 통합'!E16)),"★★★",IF(ISNUMBER(SEARCH("★★",'트래블마트 통합'!E16)),"★★",IF(ISNUMBER(SEARCH("★",'트래블마트 통합'!E16)),"★","-"))) -> - | F17: TRUE | G17: TRUE | H17: =IF(AND(F17,G17),"완료",IF(G17,"진행 완료",IF(F17,"참가 예정","미정"))) -> 완료 | I17: ='트래블마트 통합'!E16 -> 5-8 Mar Thai Teaw Thai (77th Edition) B2C
A18: ='트래블마트 통합'!E$2 -> 2026년 3월 | B18: ='트래블마트 통합'!$A17 -> 말레이시아 | C18: ='트래블마트 통합'!$B17 -> 쿠알라룸프르, 쿠칭 | D18: =IFERROR(LEFT('트래블마트 통합'!E17,FIND(CHAR(10),'트래블마트 통합'!E17)-1),'트래블마트 통합'!E17) -> MATTA Fair | E18: =IF(ISNUMBER(SEARCH("★★★",'트래블마트 통합'!E17)),"★★★",IF(ISNUMBER(SEARCH("★★",'트래블마트 통합'!E17)),"★★",IF(ISNUMBER(SEARCH("★",'트래블마트 통합'!E17)),"★","-"))) -> ★ | F18: FALSE | G18: FALSE | H18: =IF(AND(F18,G18),"완료",IF(G18,"진행 완료",IF(F18,"참가 예정","미정"))) -> 미정 | I18: ='트래블마트 통합'!E17 -> MATTA Fair 3 - 5 April 2026 [★ 선택] 말레이시아 최대 B2C
A19: ='트래블마트 통합'!E$2 -> 2026년 3월 | B19: ='트래블마트 통합'!$A21 -> 러시아 | C19: ='트래블마트 통합'!$B21 -> 모스크바 | D19: =IFERROR(LEFT('트래블마트 통합'!E21,FIND(CHAR(10),'트래블마트 통합'!E21)-1),'트래블마트 통합'!E21) -> MITT 2026 | E19: =IF(ISNUMBER(SEARCH("★★★",'트래블마트 통합'!E21)),"★★★",IF(ISNUMBER(SEARCH("★★",'트래블마트 통합'!E21)),"★★",IF(ISNUMBER(SEARCH("★",'트래블마트 통합'!E21)),"★","-"))) -> ★★ | F19: FALSE | G19: FALSE | H19: =IF(AND(F19,G19),"완료",IF(G19,"진행 완료",IF(F19,"참가 예정","미정"))) -> 미정 | I19: ='트래블마트 통합'!E21 -> MITT 2026 2026년 3월 11일 ~ 3월 13일 [★★ 중간] 러시아·CIS 최대, 러시아 outbound 핵심
A20: ='트래블마트 통합'!E$2 -> 2026년 3월 | B20: ='트래블마트 통합'!$A23 -> Qatar | C20: ='트래블마트 통합'!$B23 -> Doha | D20: =IFERROR(LEFT('트래블마트 통합'!E23,FIND(CHAR(10),'트래블마트 통합'!E23)-1),'트래블마트 통합'!E23) -> Connections Luxury Middle East 2026 | E20: =IF(ISNUMBER(SEARCH("★★★",'트래블마트 통합'!E23)),"★★★",IF(ISNUMBER(SEARCH("★★",'트래블마트 통합'!E23)),"★★",IF(ISNUMBER(SEARCH("★",'트래블마트 통합'!E23)),"★","-"))) -> ★ | F20: FALSE | G20: FALSE | H20: =IF(AND(F20,G20),"완료",IF(G20,"진행 완료",IF(F20,"참가 예정","미정"))) -> 미정 | I20: ='트래블마트 통합'!E23 -> Connections Luxury Middle East 2026 2026년 3월 29일 ~ 4월 1일 [★ 선택] 초럭셔리 바이어 행사, 하이엔드 전략용
A21: ='트래블마트 통합'!E$2 -> 2026년 3월 | B21: ='트래블마트 통합'!$A24 -> 독일 | C21: ='트래블마트 통합'!$B24 -> 베를린 오버하우젠 | D21: =IFERROR(LEFT('트래블마트 통합'!E24,FIND(CHAR(10),'트래블마트 통합'!E24)-1),'트래블마트 통합'!E24) -> ITB Berlin 2026 | E21: =IF(ISNUMBER(SEARCH("★★★",'트래블마트 통합'!E24)),"★★★",IF(ISNUMBER(SEARCH("★★",'트래블마트 통합'!E24)),"★★",IF(ISNUMBER(SEARCH("★",'트래블마트 통합'!E24)),"★","-"))) -> ★★★ | F21: FALSE | G21: FALSE | H21: =IF(AND(F21,G21),"완료",IF(G21,"진행 완료",IF(F21,"참가 예정","미정"))) -> 미정 | I21: ='트래블마트 통합'!E24 -> ITB Berlin 2026 2026년 3월 3일(화) ~ 3월 5일(목) [★★★ 최우선] 세계 1위 여행 B2B, 글로벌 파트너 확장 필수
A22: ='트래블마트 통합'!E$2 -> 2026년 3월 | B22: ='트래블마트 통합'!$A28 -> 미국 | C22: ='트래블마트 통합'!$B28 -> 플로리다주 뉴욕 | D22: =IFERROR(LEFT('트래블마트 통합'!E28,FIND(CHAR(10),'트래블마트 통합'!E28)-1),'트래블마트 통합'!E28) -> NYTTravel Show | E22: =IF(ISNUMBER(SEARCH("★★★",'트래블마트 통합'!E28)),"★★★",IF(ISNUMBER(SEARCH("★★",'트래블마트 통합'!E28)),"★★",IF(ISNUMBER(SEARCH("★",'트래블마트 통합'!E28)),"★","-"))) -> - | F22: FALSE | G22: FALSE | H22: =IF(AND(F22,G22),"완료",IF(G22,"진행 완료",IF(F22,"참가 예정","미정"))) -> 미정 | I22: ='트래블마트 통합'!E28 -> NYTTravel Show
A23: ='트래블마트 통합'!F$2 -> 2026년 4월 | B23: ='트래블마트 통합'!$A9 -> 중국 | C23: ='트래블마트 통합'!$B9 -> 광동,화동,화북,내륙 | D23: =IFERROR(LEFT('트래블마트 통합'!F9,FIND(CHAR(10),'트래블마트 통합'!F9)-1),'트래블마트 통합'!F9) -> 1차 세일즈 콜 | E23: =IF(ISNUMBER(SEARCH("★★★",'트래블마트 통합'!F9)),"★★★",IF(ISNUMBER(SEARCH("★★",'트래블마트 통합'!F9)),"★★",IF(ISNUMBER(SEARCH("★",'트래블마트 통합'!F9)),"★","-"))) -> ★★★ | F23: TRUE | G23: TRUE | H23: =IF(AND(F23,G23),"완료",IF(G23,"진행 완료",IF(F23,"참가 예정","미정"))) -> 완료 | I23: ='트래블마트 통합'!F9 -> 1차 세일즈 콜 청두, 시안, 중경 COTTM Beijing (보통 4월) [★★★ 최우선] 중국 outbound 전문 B2B
A24: ='트래블마트 통합'!F$2 -> 2026년 4월 | B24: ='트래블마트 통합'!$A15 -> 베트남 | C24: ='트래블마트 통합'!$B15 -> 호치민 하노이 | D24: =IFERROR(LEFT('트래블마트 통합'!F15,FIND(CHAR(10),'트래블마트 통합'!F15)-1),'트래블마트 통합'!F15) -> Vietnam International Travel Mart HANOI | E24: =IF(ISNUMBER(SEARCH("★★★",'트래블마트 통합'!F15)),"★★★",IF(ISNUMBER(SEARCH("★★",'트래블마트 통합'!F15)),"★★",IF(ISNUMBER(SEARCH("★",'트래블마트 통합'!F15)),"★","-"))) -> ★★ | F24: FALSE | G24: FALSE | H24: =IF(AND(F24,G24),"완료",IF(G24,"진행 완료",IF(F24,"참가 예정","미정"))) -> 미정 | I24: ='트래블마트 통합'!F15 -> Vietnam International Travel Mart HANOI [★★ 중간] 북베트남 B2B+B2C
A25: ='트래블마트 통합'!F$2 -> 2026년 4월 | B25: ='트래블마트 통합'!$A24 -> 독일 | C25: ='트래블마트 통합'!$B24 -> 베를린 오버하우젠 | D25: =IFERROR(LEFT('트래블마트 통합'!F24,FIND(CHAR(10),'트래블마트 통합'!F24)-1),'트래블마트 통합'!F24) -> Germany Travel Mart (GTM) 2026 | E25: =IF(ISNUMBER(SEARCH("★★★",'트래블마트 통합'!F24)),"★★★",IF(ISNUMBER(SEARCH("★★",'트래블마트 통합'!F24)),"★★",IF(ISNUMBER(SEARCH("★",'트래블마트 통합'!F24)),"★","-"))) -> ★ | F25: FALSE | G25: FALSE | H25: =IF(AND(F25,G25),"완료",IF(G25,"진행 완료",IF(F25,"참가 예정","미정"))) -> 미정 | I25: ='트래블마트 통합'!F24 -> Germany Travel Mart (GTM) 2026 2026년 4월 19일 ~ 21일 [★ 선택] 독일 관광청 주최, 유럽 인바운드 중심
A26: ='트래블마트 통합'!F$2 -> 2026년 4월 | B26: ='트래블마트 통합'!$A28 -> 미국 | C26: ='트래블마트 통합'!$B28 -> 플로리다주 뉴욕 | D26: =IFERROR(LEFT('트래블마트 통합'!F28,FIND(CHAR(10),'트래블마트 통합'!F28)-1),'트래블마트 통합'!F28) -> NYTTravel Show | E26: =IF(ISNUMBER(SEARCH("★★★",'트래블마트 통합'!F28)),"★★★",IF(ISNUMBER(SEARCH("★★",'트래블마트 통합'!F28)),"★★",IF(ISNUMBER(SEARCH("★",'트래블마트 통합'!F28)),"★","-"))) -> - | F26: FALSE | G26: FALSE | H26: =IF(AND(F26,G26),"완료",IF(G26,"진행 완료",IF(F26,"참가 예정","미정"))) -> 미정 | I26: ='트래블마트 통합'!F28 -> NYTTravel Show
A27: ='트래블마트 통합'!F$2 -> 2026년 4월 | B27: ='트래블마트 통합'!$A30 -> South Africa | C27: ='트래블마트 통합'!$B30 -> Cape Town | D27: =IFERROR(LEFT('트래블마트 통합'!F30,FIND(CHAR(10),'트래블마트 통합'!F30)-1),'트래블마트 통합'!F30) -> WTM Africa 2026 | E27: =IF(ISNUMBER(SEARCH("★★★",'트래블마트 통합'!F30)),"★★★",IF(ISNUMBER(SEARCH("★★",'트래블마트 통합'!F30)),"★★",IF(ISNUMBER(SEARCH("★",'트래블마트 통합'!F30)),"★","-"))) -> ★ | F27: FALSE | G27: FALSE | H27: =IF(AND(F27,G27),"완료",IF(G27,"진행 완료",IF(F27,"참가 예정","미정"))) -> 미정 | I27: ='트래블마트 통합'!F30 -> WTM Africa 2026 [★ 선택] 아프리카 시장 접근
A28: ='트래블마트 통합'!F$2 -> 2026년 4월 | B28: ='트래블마트 통합'!$A31 -> 브라질 | C28: ='트래블마트 통합'!$B31 -> 상파울루 | D28: =IFERROR(LEFT('트래블마트 통합'!F31,FIND(CHAR(10),'트래블마트 통합'!F31)-1),'트래블마트 통합'!F31) -> WTM Latin America 2026 | E28: =IF(ISNUMBER(SEARCH("★★★",'트래블마트 통합'!F31)),"★★★",IF(ISNUMBER(SEARCH("★★",'트래블마트 통합'!F31)),"★★",IF(ISNUMBER(SEARCH("★",'트래블마트 통합'!F31)),"★","-"))) -> ★ | F28: FALSE | G28: FALSE | H28: =IF(AND(F28,G28),"완료",IF(G28,"진행 완료",IF(F28,"참가 예정","미정"))) -> 미정 | I28: ='트래블마트 통합'!F31 -> WTM Latin America 2026 2026년 4월 14-16일 [★ 선택] 남미 최대 B2B, 라틴 바이어 네트워크
A29: ='트래블마트 통합'!G$2 -> 2026년 5월 | B29: ='트래블마트 통합'!$A9 -> 중국 | C29: ='트래블마트 통합'!$B9 -> 광동,화동,화북,내륙 | D29: =IFERROR(LEFT('트래블마트 통합'!G9,FIND(CHAR(10),'트래블마트 통합'!G9)-1),'트래블마트 통합'!G9) -> 5/26–5/28 – ITB China | E29: =IF(ISNUMBER(SEARCH("★★★",'트래블마트 통합'!G9)),"★★★",IF(ISNUMBER(SEARCH("★★",'트래블마트 통합'!G9)),"★★",IF(ISNUMBER(SEARCH("★",'트래블마트 통합'!G9)),"★","-"))) -> ★★★ | F29: TRUE | G29: TRUE | H29: =IF(AND(F29,G29),"완료",IF(G29,"진행 완료",IF(F29,"참가 예정","미정"))) -> 완료 | I29: ='트래블마트 통합'!G9 -> 5/26–5/28 – ITB China 1차 Shanghai GITF (Guangzhou International Travel Fair) 5/21–23 [★★★ 최우선] 중국 outbound 최상위 B2B
A30: ='트래블마트 통합'!G$2 -> 2026년 5월 | B30: ='트래블마트 통합'!$A10 -> 한국 | C30: ='트래블마트 통합'!$B10 -> 서울 | D30: =IFERROR(LEFT('트래블마트 통합'!G10,FIND(CHAR(10),'트래블마트 통합'!G10)-1),'트래블마트 통합'!G10) -> 일산 트래블마트 | E30: =IF(ISNUMBER(SEARCH("★★★",'트래블마트 통합'!G10)),"★★★",IF(ISNUMBER(SEARCH("★★",'트래블마트 통합'!G10)),"★★",IF(ISNUMBER(SEARCH("★",'트래블마트 통합'!G10)),"★","-"))) -> - | F30: TRUE | G30: TRUE | H30: =IF(AND(F30,G30),"완료",IF(G30,"진행 완료",IF(F30,"참가 예정","미정"))) -> 완료 | I30: ='트래블마트 통합'!G10 -> 일산 트래블마트 5월 14~17일
A31: ='트래블마트 통합'!G$2 -> 2026년 5월 | B31: ='트래블마트 통합'!$A12 -> 대만 | C31: ='트래블마트 통합'!$B12 -> 타이베이 | D31: =IFERROR(LEFT('트래블마트 통합'!G12,FIND(CHAR(10),'트래블마트 통합'!G12)-1),'트래블마트 통합'!G12) -> 5/22–5/25 – Taipei Tourism Expo (TTE) | E31: =IF(ISNUMBER(SEARCH("★★★",'트래블마트 통합'!G12)),"★★★",IF(ISNUMBER(SEARCH("★★",'트래블마트 통합'!G12)),"★★",IF(ISNUMBER(SEARCH("★",'트래블마트 통합'!G12)),"★","-"))) -> ★ | F31: FALSE | G31: FALSE | H31: =IF(AND(F31,G31),"완료",IF(G31,"진행 완료",IF(F31,"참가 예정","미정"))) -> 미정 | I31: ='트래블마트 통합'!G12 -> 5/22–5/25 – Taipei Tourism Expo (TTE) [★ 선택] 대만 최대 B2C, FIT 시장 강함
A32: ='트래블마트 통합'!G$2 -> 2026년 5월 | B32: ='트래블마트 통합'!$A19 -> 인도네시아 | C32: ='트래블마트 통합'!$B19 -> 자카르타 | D32: =IFERROR(LEFT('트래블마트 통합'!G19,FIND(CHAR(10),'트래블마트 통합'!G19)-1),'트래블마트 통합'!G19) -> BBTF (Bali & Beyond Travel Fair) 2026 | E32: =IF(ISNUMBER(SEARCH("★★★",'트래블마트 통합'!G19)),"★★★",IF(ISNUMBER(SEARCH("★★",'트래블마트 통합'!G19)),"★★",IF(ISNUMBER(SEARCH("★",'트래블마트 통합'!G19)),"★","-"))) -> - | F32: FALSE | G32: FALSE | H32: =IF(AND(F32,G32),"완료",IF(G32,"진행 완료",IF(F32,"참가 예정","미정"))) -> 미정 | I32: ='트래블마트 통합'!G19 -> BBTF (Bali & Beyond Travel Fair) 2026 날짜: 2026년 5월 28일(목) ~ 5월 30일(토) 특징: 상반기 동남아시아 일정 중 호텔 소싱에 가장 중요한 행사
A33: ='트래블마트 통합'!G$2 -> 2026년 5월 | B33: ='트래블마트 통합'!$A22 -> UAE | C33: ='트래블마트 통합'!$B22 -> Dubai | D33: =IFERROR(LEFT('트래블마트 통합'!G22,FIND(CHAR(10),'트래블마트 통합'!G22)-1),'트래블마트 통합'!G22) -> Arabian Travel Market (ATM) 2026 | E33: =IF(ISNUMBER(SEARCH("★★★",'트래블마트 통합'!G22)),"★★★",IF(ISNUMBER(SEARCH("★★",'트래블마트 통합'!G22)),"★★",IF(ISNUMBER(SEARCH("★",'트래블마트 통합'!G22)),"★","-"))) -> ★★★ | F33: TRUE | G33: FALSE | H33: =IF(AND(F33,G33),"완료",IF(G33,"진행 완료",IF(F33,"참가 예정","미정"))) -> 참가 예정 | I33: ='트래블마트 통합'!G22 -> Arabian Travel Market (ATM) 2026 2026년 5월 4일 ~ 5월 7일 [★★★ 최우선] 중동 최대 여행 B2B, GCC 바이어 중심
A34: ='트래블마트 통합'!G$2 -> 2026년 5월 | B34: ='트래블마트 통합'!$A25 -> 호주 | C34: ='트래블마트 통합'!$B25 -> 시드니, 애들레이드 | D34: =IFERROR(LEFT('트래블마트 통합'!G25,FIND(CHAR(10),'트래블마트 통합'!G25)-1),'트래블마트 통합'!G25) -> 5/10–5/14 – Australian Tourism Exchange (ATE) | E34: =IF(ISNUMBER(SEARCH("★★★",'트래블마트 통합'!G25)),"★★★",IF(ISNUMBER(SEARCH("★★",'트래블마트 통합'!G25)),"★★",IF(ISNUMBER(SEARCH("★",'트래블마트 통합'!G25)),"★","-"))) -> ★ | F34: FALSE | G34: FALSE | H34: =IF(AND(F34,G34),"완료",IF(G34,"진행 완료",IF(F34,"참가 예정","미정"))) -> 미정 | I34: ='트래블마트 통합'!G25 -> 5/10–5/14 – Australian Tourism Exchange (ATE) [★ 선택] 오세아니아 최대 B2B
A35: ='트래블마트 통합'!G$2 -> 2026년 5월 | B35: ='트래블마트 통합'!$A28 -> 미국 | C35: ='트래블마트 통합'!$B28 -> 플로리다주 뉴욕 | D35: =IFERROR(LEFT('트래블마트 통합'!G28,FIND(CHAR(10),'트래블마트 통합'!G28)-1),'트래블마트 통합'!G28) -> IPW 2026 | E35: =IF(ISNUMBER(SEARCH("★★★",'트래블마트 통합'!G28)),"★★★",IF(ISNUMBER(SEARCH("★★",'트래블마트 통합'!G28)),"★★",IF(ISNUMBER(SEARCH("★",'트래블마트 통합'!G28)),"★","-"))) -> ★ | F35: FALSE | G35: FALSE | H35: =IF(AND(F35,G35),"완료",IF(G35,"진행 완료",IF(F35,"참가 예정","미정"))) -> 미정 | I35: ='트래블마트 통합'!G28 -> IPW 2026 2026년 5월 17-21일 [★ 선택] 미국 인바운드 최대 B2B 행사
A36: ='트래블마트 통합'!H$2 -> 2026년 6월 | B36: ='트래블마트 통합'!$A10 -> 한국 | C36: ='트래블마트 통합'!$B10 -> 서울 | D36: =IFERROR(LEFT('트래블마트 통합'!H10,FIND(CHAR(10),'트래블마트 통합'!H10)-1),'트래블마트 통합'!H10) -> 6/4–6/7 – Seoul International Travel Fair (SITF) | E36: =IF(ISNUMBER(SEARCH("★★★",'트래블마트 통합'!H10)),"★★★",IF(ISNUMBER(SEARCH("★★",'트래블마트 통합'!H10)),"★★",IF(ISNUMBER(SEARCH("★",'트래블마트 통합'!H10)),"★","-"))) -> ★ | F36: FALSE | G36: FALSE | H36: =IF(AND(F36,G36),"완료",IF(G36,"진행 완료",IF(F36,"참가 예정","미정"))) -> 미정 | I36: ='트래블마트 통합'!H10 -> 6/4–6/7 – Seoul International Travel Fair (SITF) [★ 선택] 한국 최대 여행박람회
A37: ='트래블마트 통합'!H$2 -> 2026년 6월 | B37: ='트래블마트 통합'!$A13 -> 홍콩 | C37: ='트래블마트 통합'!$B13 -> 홍콩 | D37: =IFERROR(LEFT('트래블마트 통합'!H13,FIND(CHAR(10),'트래블마트 통합'!H13)-1),'트래블마트 통합'!H13) -> ITE Hong Kong | E37: =IF(ISNUMBER(SEARCH("★★★",'트래블마트 통합'!H13)),"★★★",IF(ISNUMBER(SEARCH("★★",'트래블마트 통합'!H13)),"★★",IF(ISNUMBER(SEARCH("★",'트래블마트 통합'!H13)),"★","-"))) -> ★★ | F37: FALSE | G37: FALSE | H37: =IF(AND(F37,G37),"완료",IF(G37,"진행 완료",IF(F37,"참가 예정","미정"))) -> 미정 | I37: ='트래블마트 통합'!H13 -> ITE Hong Kong 6월 11~14일 전후 [★★ 중간] 홍콩–광둥 outbound 중심
A38: ='트래블마트 통합'!H$2 -> 2026년 6월 | B38: ='트래블마트 통합'!$A16 -> 태국 | C38: ='트래블마트 통합'!$B16 -> 방콕 | D38: =IFERROR(LEFT('트래블마트 통합'!H16,FIND(CHAR(10),'트래블마트 통합'!H16)-1),'트래블마트 통합'!H16) -> TTM+ (Thailand Travel Mart Plus) 2026 | E38: =IF(ISNUMBER(SEARCH("★★★",'트래블마트 통합'!H16)),"★★★",IF(ISNUMBER(SEARCH("★★",'트래블마트 통합'!H16)),"★★",IF(ISNUMBER(SEARCH("★",'트래블마트 통합'!H16)),"★","-"))) -> - | F38: FALSE | G38: FALSE | H38: =IF(AND(F38,G38),"완료",IF(G38,"진행 완료",IF(F38,"참가 예정","미정"))) -> 미정 | I38: ='트래블마트 통합'!H16 -> TTM+ (Thailand Travel Mart Plus) 2026 예상 날짜: 2026년 6월 중 (보통 6월 둘째 주) 장소: 미정 특징: 태국 관광청(TAT) 주관 행사
A39: ='트래블마트 통합'!H$2 -> 2026년 6월 | B39: ='트래블마트 통합'!$A18 -> 싱가포르 | C39: ='트래블마트 통합'!$B18 -> 마리나베이 | D39: =IFERROR(LEFT('트래블마트 통합'!H18,FIND(CHAR(10),'트래블마트 통합'!H18)-1),'트래블마트 통합'!H18) -> ILTM Asia Pacific 2026 | E39: =IF(ISNUMBER(SEARCH("★★★",'트래블마트 통합'!H18)),"★★★",IF(ISNUMBER(SEARCH("★★",'트래블마트 통합'!H18)),"★★",IF(ISNUMBER(SEARCH("★",'트래블마트 통합'!H18)),"★","-"))) -> ★ | F39: FALSE | G39: FALSE | H39: =IF(AND(F39,G39),"완료",IF(G39,"진행 완료",IF(F39,"참가 예정","미정"))) -> 미정 | I39: ='트래블마트 통합'!H18 -> ILTM Asia Pacific 2026 2026년 6월 29일 ~ 7월 2일 [★ 선택] 아시아 럭셔리 여행 최상위 행사
A40: ='트래블마트 통합'!H$2 -> 2026년 6월 | B40: ='트래블마트 통합'!$A19 -> 인도네시아 | C40: ='트래블마트 통합'!$B19 -> 자카르타 | D40: =IFERROR(LEFT('트래블마트 통합'!H19,FIND(CHAR(10),'트래블마트 통합'!H19)-1),'트래블마트 통합'!H19) -> Travel Meet Asia 2026 | E40: =IF(ISNUMBER(SEARCH("★★★",'트래블마트 통합'!H19)),"★★★",IF(ISNUMBER(SEARCH("★★",'트래블마트 통합'!H19)),"★★",IF(ISNUMBER(SEARCH("★",'트래블마트 통합'!H19)),"★","-"))) -> ★ | F40: TRUE | G40: TRUE | H40: =IF(AND(F40,G40),"완료",IF(G40,"진행 완료",IF(F40,"참가 예정","미정"))) -> 완료 | I40: ='트래블마트 통합'!H19 -> Travel Meet Asia 2026 2026년 6월 23-24일 [★ 선택] 아세안 B2B 네트워크 허브
A41: ='트래블마트 통합'!I$2 -> 2026년 7월 | B41: ='트래블마트 통합'!$A9 -> 중국 | C41: ='트래블마트 통합'!$B9 -> 광동,화동,화북,내륙 | D41: =IFERROR(LEFT('트래블마트 통합'!I9,FIND(CHAR(10),'트래블마트 통합'!I9)-1),'트래블마트 통합'!I9) -> 2차 세일즈 콜 | E41: =IF(ISNUMBER(SEARCH("★★★",'트래블마트 통합'!I9)),"★★★",IF(ISNUMBER(SEARCH("★★",'트래블마트 통합'!I9)),"★★",IF(ISNUMBER(SEARCH("★",'트래블마트 통합'!I9)),"★","-"))) -> - | F41: TRUE | G41: TRUE | H41: =IF(AND(F41,G41),"완료",IF(G41,"진행 완료",IF(F41,"참가 예정","미정"))) -> 완료 | I41: ='트래블마트 통합'!I9 -> 2차 세일즈 콜 심천+대만+홍콩
...

Sheet Dev Tracker
A1: API Integration Dev Tracker (IT / Dev Shared) — Actual Progress History by Stage Process | AA1: Stage Weights (progress calc · maps to cols M~W)
A2: Project / Dev Info | K2: Progress Status (Auto-calculated) | AA2: ① | AB2: ② | AC2: ③ | AD2: ④ | AE2: ⑤ | AF2: ⑥ | AG2: ⑦ | AH2: ⑧ | AI2: ⑨ | AJ2: ⑩ | AK2: ⑪
A3: No. | B3: Status | C3: Country | D3: Project | E3: Category | F3: Biz Impact | G3: OHMY Dev Load | H3: Switching | I3: Handling Team | J3: PIC (Sales) | K3: Progress % | L3: Last Activity | M3: Days Elapsed | N3: Delay Check | O3: ① NDA Signed (20%) | P3: ② Contract Signed (30%) | Q3: ③ SLA Finalized (40%) | R3: ④ Dev Kickoff Planned (45%) | S3: ⑤ Dev Kickoff / SPEC·DEV Key (50%) / Credential | T3: ⑥ Certification (60%) | U3: ⑦ Live Test (70%) | V3: ⑧ Dev Completion Planned (75%) | W3: ⑨ Live Key Open (80%) | X3: ⑩ First Booking (90%) | Y3: ⑪ API Live Complete (100%) | Z3: Status (manual backup) | AA3: 0.2 | AB3: 0.3 | AC3: 0.4 | AD3: 0.45 | AE3: 0.5 | AF3: 0.6 | AG3: 0.7 | AH3: 0.75 | AI3: 0.8 | AJ3: 0.9 | AK3: 1 | AL3: Dev Owner | AM3: Target Go-Live | AN3: Blocker | AO3: Note | AP3: Hold/Drop
A4: =IF($D4="","",COUNTA($D$4:$D4)) -> 1 | B4: =IF($D4="","",IF($L4="","Contact",LOOKUP($K4,$AA$5:$AA$8,$AB$5:$AB$8))) -> Contact | C4: Korea | D4: HANHWA Hotel & Resort | E4: CRS | F4: High | G4: 🔴 Full (100%) | I4: SLA | J4: Sophia | K4: {=IF($D4="","",SUMPRODUCT(MAX(($O4:$Y4<>"")*$AA$3:$AK$3)))} -> 0 | L4: =IF(COUNT($O4:$Y4)=0,"",MAX($O4:$Y4)) | M4: =IF($L4="","",TODAY()-$L4) | N4: =IF($L4="","No Record",IF($K4>=1,"Live",IF($M4>=90,"Stalled 90d+",IF($M4>=60,"Stalled 60d+",IF($M4>=30,"Stalled 30d+","In Progress"))))) -> No Record | Z4: Contact
A5: =IF($D5="","",COUNTA($D$4:$D5)) -> 2 | B5: =IF($D5="","",IF($L5="","Contact",LOOKUP($K5,$AA$5:$AA$8,$AB$5:$AB$8))) -> In Development | C5: China | D5: Shiji | E5: Switching System | F5: High | G5: 🟡 Half (50%) | I5: SLA | J5: Sophia | K5: {=IF($D5="","",SUMPRODUCT(MAX(($O5:$Y5<>"")*$AA$3:$AK$3)))} -> 0.45 | L5: =IF(COUNT($O5:$Y5)=0,"",MAX($O5:$Y5)) -> 46237 | M5: =IF($L5="","",TODAY()-$L5) -> 19 | N5: =IF($L5="","No Record",IF($K5>=1,"Live",IF($M5>=90,"Stalled 90d+",IF($M5>=60,"Stalled 60d+",IF($M5>=30,"Stalled 30d+","In Progress"))))) -> In Progress | O5: 45504 | P5: 46199 | R5: 46237 | Z5: In Development | AA5: 0.2 | AB5: NDA/Contract
A6: =IF($D6="","",COUNTA($D$4:$D6)) -> 3 | B6: =IF($D6="","",IF($L6="","Contact",LOOKUP($K6,$AA$5:$AA$8,$AB$5:$AB$8))) -> Contact | C6: Spain | D6: TGX | E6: Switching System | F6: High | G6: 🟡 Half (50%) | I6: SLA | J6: Sophia | K6: {=IF($D6="","",SUMPRODUCT(MAX(($O6:$Y6<>"")*$AA$3:$AK$3)))} -> 0 | L6: =IF(COUNT($O6:$Y6)=0,"",MAX($O6:$Y6)) | M6: =IF($L6="","",TODAY()-$L6) | N6: =IF($L6="","No Record",IF($K6>=1,"Live",IF($M6>=90,"Stalled 90d+",IF($M6>=60,"Stalled 60d+",IF($M6>=30,"Stalled 30d+","In Progress"))))) -> No Record | Z6: NDA/Contract | AA6: 0.45 | AB6: In Development
A7: =IF($D7="","",COUNTA($D$4:$D7)) -> 4 | B7: =IF($D7="","",IF($L7="","Contact",LOOKUP($K7,$AA$5:$AA$8,$AB$5:$AB$8))) -> Contact | C7: Spain | D7: Juniper | E7: Switching System | F7: Mid | G7: 🟢 Minimal (5-10%) | I7: SLA | J7: Sophia | K7: {=IF($D7="","",SUMPRODUCT(MAX(($O7:$Y7<>"")*$AA$3:$AK$3)))} -> 0 | L7: =IF(COUNT($O7:$Y7)=0,"",MAX($O7:$Y7)) | M7: =IF($L7="","",TODAY()-$L7) | N7: =IF($L7="","No Record",IF($K7>=1,"Live",IF($M7>=90,"Stalled 90d+",IF($M7>=60,"Stalled 60d+",IF($M7>=30,"Stalled 30d+","In Progress"))))) -> No Record | Z7: Contact | AA7: 0.7 | AB7: Testing
A8: =IF($D8="","",COUNTA($D$4:$D8)) -> 5 | B8: =IF($D8="","",IF($L8="","Contact",LOOKUP($K8,$AA$5:$AA$8,$AB$5:$AB$8))) -> Contact | C8: Singapore | D8: TAN | E8: Switching System | F8: Low | G8: 🔴 Full (100%) | I8: SLA | J8: Sophia | K8: {=IF($D8="","",SUMPRODUCT(MAX(($O8:$Y8<>"")*$AA$3:$AK$3)))} -> 0 | L8: =IF(COUNT($O8:$Y8)=0,"",MAX($O8:$Y8)) | M8: =IF($L8="","",TODAY()-$L8) | N8: =IF($L8="","No Record",IF($K8>=1,"Live",IF($M8>=90,"Stalled 90d+",IF($M8>=60,"Stalled 60d+",IF($M8>=30,"Stalled 30d+","In Progress"))))) -> No Record | Z8: Contact | AA8: 0.8 | AB8: Live
A9: =IF($D9="","",COUNTA($D$4:$D9)) -> 6 | B9: =IF($D9="","",IF($L9="","Contact",LOOKUP($K9,$AA$5:$AA$8,$AB$5:$AB$8))) -> Contact | D9: IOL | E9: Switching System | F9: Low | I9: SLA | J9: Sophia | K9: {=IF($D9="","",SUMPRODUCT(MAX(($O9:$Y9<>"")*$AA$3:$AK$3)))} -> 0 | N9: =IF($L9="","No Record",IF($K9>=1,"Live",IF($M9>=90,"Stalled 90d+",IF($M9>=60,"Stalled 60d+",IF($M9>=30,"Stalled 30d+","In Progress"))))) -> No Record
A10: =IF($D10="","",COUNTA($D$4:$D10)) -> 7 | B10: =IF($D10="","",IF($L10="","Contact",LOOKUP($K10,$AA$5:$AA$8,$AB$5:$AB$8))) -> Contact | C10: China | D10: Derbysoft | E10: Switching System | F10: Low | G10: 🔴 Full (100%) | I10: SLA | J10: Sophia | K10: {=IF($D10="","",SUMPRODUCT(MAX(($O10:$Y10<>"")*$AA$3:$AK$3)))} -> 0 | L10: =IF(COUNT($O10:$Y10)=0,"",MAX($O10:$Y10)) | M10: =IF($L10="","",TODAY()-$L10) | N10: =IF($L10="","No Record",IF($K10>=1,"Live",IF($M10>=90,"Stalled 90d+",IF($M10>=60,"Stalled 60d+",IF($M10>=30,"Stalled 30d+","In Progress"))))) -> No Record | Z10: Contact
A11: =IF($D11="","",COUNTA($D$4:$D11)) -> 8 | B11: =IF($D11="","",IF($L11="","Contact",LOOKUP($K11,$AA$5:$AA$8,$AB$5:$AB$8))) -> Contact | C11: USA | D11: Synxis | E11: Switching System | F11: Low | G11: 🔴 Full (100%) | I11: SLA | J11: Sophia | K11: {=IF($D11="","",SUMPRODUCT(MAX(($O11:$Y11<>"")*$AA$3:$AK$3)))} -> 0 | L11: =IF(COUNT($O11:$Y11)=0,"",MAX($O11:$Y11)) | M11: =IF($L11="","",TODAY()-$L11) | N11: =IF($L11="","No Record",IF($K11>=1,"Live",IF($M11>=90,"Stalled 90d+",IF($M11>=60,"Stalled 60d+",IF($M11>=30,"Stalled 30d+","In Progress"))))) -> No Record | Z11: Contact
A12: =IF($D12="","",COUNTA($D$4:$D12)) -> 9 | B12: =IF($D12="","",IF($L12="","Contact",LOOKUP($K12,$AA$5:$AA$8,$AB$5:$AB$8))) -> Contact | D12: 11infortec | E12: Switching System | F12: Low | G12: 🔴 Full (100%) | I12: SLA | J12: Sophia | K12: {=IF($D12="","",SUMPRODUCT(MAX(($O12:$Y12<>"")*$AA$3:$AK$3)))} -> 0 | L12: =IF(COUNT($O12:$Y12)=0,"",MAX($O12:$Y12)) | M12: =IF($L12="","",TODAY()-$L12) | N12: =IF($L12="","No Record",IF($K12>=1,"Live",IF($M12>=90,"Stalled 90d+",IF($M12>=60,"Stalled 60d+",IF($M12>=30,"Stalled 30d+","In Progress"))))) -> No Record | Z12: Contact
A13: =IF($D13="","",COUNTA($D$4:$D13)) -> 10 | B13: =IF($D13="","",IF($L13="","Contact",LOOKUP($K13,$AA$5:$AA$8,$AB$5:$AB$8))) -> Testing | C13: Hong Kong | D13: Klook | E13: Channel API | F13: High | G13: 🔴 Full (100%) | I13: GSM | J13: Grace | K13: {=IF($D13="","",SUMPRODUCT(MAX(($O13:$Y13<>"")*$AA$3:$AK$3)))} -> 0.75 | L13: =IF(COUNT($O13:$Y13)=0,"",MAX($O13:$Y13)) -> 45965 | M13: =IF($L13="","",TODAY()-$L13) -> 291 | N13: =IF($L13="","No Record",IF($K13>=1,"Live",IF($M13>=90,"Stalled 90d+",IF($M13>=60,"Stalled 60d+",IF($M13>=30,"Stalled 30d+","In Progress"))))) -> Stalled 90d+ | R13: 45962 | S13: 45962 | T13: 45963 | U13: 45964 | V13: 45965 | Z13: Testing
B14: =IF($D14="","",IF($L14="","Contact",LOOKUP($K14,$AA$5:$AA$8,$AB$5:$AB$8))) -> NDA/Contract | C14: Indonesia | D14: Tiket.com | E14: Channel API | F14: High | G14: 🟡 Half (50%) | I14: GSM | J14: Aiden | K14: {=IF($D14="","",SUMPRODUCT(MAX(($O14:$Y14<>"")*$AA$3:$AK$3)))} -> 0.2 | L14: =IF(COUNT($O14:$Y14)=0,"",MAX($O14:$Y14)) -> 46246 | N14: =IF($L14="","No Record",IF($K14>=1,"Live",IF($M14>=90,"Stalled 90d+",IF($M14>=60,"Stalled 60d+",IF($M14>=30,"Stalled 30d+","In Progress"))))) -> In Progress | O14: 46246
A15: =IF($D15="","",COUNTA($D$4:$D15)) -> 12 | B15: =IF($D15="","",IF($L15="","Contact",LOOKUP($K15,$AA$5:$AA$8,$AB$5:$AB$8))) -> Contact | C15: Israel | D15: GGT (Go Global) | E15: Channel API | F15: High | G15: 🔴 Full (100%) | I15: GSM | J15: Aiden | K15: {=IF($D15="","",SUMPRODUCT(MAX(($O15:$Y15<>"")*$AA$3:$AK$3)))} -> 0 | L15: =IF(COUNT($O15:$Y15)=0,"",MAX($O15:$Y15)) | M15: =IF($L15="","",TODAY()-$L15) | N15: =IF($L15="","No Record",IF($K15>=1,"Live",IF($M15>=90,"Stalled 90d+",IF($M15>=60,"Stalled 60d+",IF($M15>=30,"Stalled 30d+","In Progress"))))) -> No Record | Z15: In Development
A16: =IF($D16="","",COUNTA($D$4:$D16)) -> 13 | B16: =IF($D16="","",IF($L16="","Contact",LOOKUP($K16,$AA$5:$AA$8,$AB$5:$AB$8))) -> Contact | C16: India | D16: TBO | E16: Channel API | F16: High | G16: 🔴 Full (100%) | I16: GSM | J16: Aiden | K16: {=IF($D16="","",SUMPRODUCT(MAX(($O16:$Y16<>"")*$AA$3:$AK$3)))} -> 0 | L16: =IF(COUNT($O16:$Y16)=0,"",MAX($O16:$Y16)) | M16: =IF($L16="","",TODAY()-$L16) | N16: =IF($L16="","No Record",IF($K16>=1,"Live",IF($M16>=90,"Stalled 90d+",IF($M16>=60,"Stalled 60d+",IF($M16>=30,"Stalled 30d+","In Progress"))))) -> No Record | Z16: NDA/Contract
A17: =IF($D17="","",COUNTA($D$4:$D17)) -> 14 | B17: =IF($D17="","",IF($L17="","Contact",LOOKUP($K17,$AA$5:$AA$8,$AB$5:$AB$8))) -> Contact | C17: Russia | D17: RateHawk | E17: Channel API | F17: High | G17: 🔴 Full (100%) | I17: GSM | J17: Aiden | K17: {=IF($D17="","",SUMPRODUCT(MAX(($O17:$Y17<>"")*$AA$3:$AK$3)))} -> 0 | L17: =IF(COUNT($O17:$Y17)=0,"",MAX($O17:$Y17)) | M17: =IF($L17="","",TODAY()-$L17) | N17: =IF($L17="","No Record",IF($K17>=1,"Live",IF($M17>=90,"Stalled 90d+",IF($M17>=60,"Stalled 60d+",IF($M17>=30,"Stalled 30d+","In Progress"))))) -> No Record | Z17: NDA/Contract
A18: =IF($D18="","",COUNTA($D$4:$D18)) -> 15 | B18: =IF($D18="","",IF($L18="","Contact",LOOKUP($K18,$AA$5:$AA$8,$AB$5:$AB$8))) -> Contact | C18: Singapore | D18: Luxury Tours | E18: Channel API | F18: Mid | G18: 🟢 Minimal (5-10%) | H18: TGX | I18: GSM | J18: Aiden | K18: {=IF($D18="","",SUMPRODUCT(MAX(($O18:$Y18<>"")*$AA$3:$AK$3)))} -> 0 | L18: =IF(COUNT($O18:$Y18)=0,"",MAX($O18:$Y18)) | M18: =IF($L18="","",TODAY()-$L18) | N18: =IF($L18="","No Record",IF($K18>=1,"Live",IF($M18>=90,"Stalled 90d+",IF($M18>=60,"Stalled 60d+",IF($M18>=30,"Stalled 30d+","In Progress"))))) -> No Record | Z18: NDA/Contract
A19: =IF($D19="","",COUNTA($D$4:$D19)) -> 16 | B19: =IF($D19="","",IF($L19="","Contact",LOOKUP($K19,$AA$5:$AA$8,$AB$5:$AB$8))) -> In Development | C19: Russia | D19: Travelata(Vivatech) | E19: Channel API | F19: High | G19: 🟢 Minimal (5-11%) | I19: GSM | J19: Aiden | K19: {=IF($D19="","",SUMPRODUCT(MAX(($O19:$Y19<>"")*$AA$3:$AK$3)))} -> 0.5 | L19: =IF(COUNT($O19:$Y19)=0,"",MAX($O19:$Y19)) -> 46253 | M19: =IF($L19="","",TODAY()-$L19) -> 3 | N19: =IF($L19="","No Record",IF($K19>=1,"Live",IF($M19>=90,"Stalled 90d+",IF($M19>=60,"Stalled 60d+",IF($M19>=30,"Stalled 30d+","In Progress"))))) -> In Progress | O19: 46252 | P19: 46253 | R19: 46253 | S19: 46253 | Z19: NDA/Contract
A20: =IF($D20="","",COUNTA($D$4:$D20)) -> 17 | B20: =IF($D20="","",IF($L20="","Contact",LOOKUP($K20,$AA$5:$AA$8,$AB$5:$AB$8))) -> NDA/Contract | C20: Singapore | D20: Within Earth | E20: Channel API | F20: Mid | G20: 🟢 Minimal (5-15%) | I20: GSM | J20: Aiden | K20: {=IF($D20="","",SUMPRODUCT(MAX(($O20:$Y20<>"")*$AA$3:$AK$3)))} -> 0.2 | L20: =IF(COUNT($O20:$Y20)=0,"",MAX($O20:$Y20)) -> 45898 | M20: =IF($L20="","",TODAY()-$L20) -> 358 | N20: =IF($L20="","No Record",IF($K20>=1,"Live",IF($M20>=90,"Stalled 90d+",IF($M20>=60,"Stalled 60d+",IF($M20>=30,"Stalled 30d+","In Progress"))))) -> Stalled 90d+ | O20: 45898 | Z20: NDA/Contract
A21: =IF($D21="","",COUNTA($D$4:$D21)) -> 18 | B21: =IF($D21="","",IF($L21="","Contact",LOOKUP($K21,$AA$5:$AA$8,$AB$5:$AB$8))) -> Contact | C21: Thailand | D21: Pax2night | E21: Channel API | F21: Mid | G21: 🟢 Minimal (5-16%) | H21: TGX | I21: GSM | J21: Aiden | K21: {=IF($D21="","",SUMPRODUCT(MAX(($O21:$Y21<>"")*$AA$3:$AK$3)))} -> 0 | L21: =IF(COUNT($O21:$Y21)=0,"",MAX($O21:$Y21)) | M21: =IF($L21="","",TODAY()-$L21) | N21: =IF($L21="","No Record",IF($K21>=1,"Live",IF($M21>=90,"Stalled 90d+",IF($M21>=60,"Stalled 60d+",IF($M21>=30,"Stalled 30d+","In Progress"))))) -> No Record | Z21: NDA/Contract
A22: =IF($D22="","",COUNTA($D$4:$D22)) -> 19 | B22: =IF($D22="","",IF($L22="","Contact",LOOKUP($K22,$AA$5:$AA$8,$AB$5:$AB$8))) -> Contact | C22: UAE | D22: Happy Travel | E22: Channel API | F22: Mid | G22: 🟢 Minimal (5-17%) | I22: GSM | J22: Aiden | K22: {=IF($D22="","",SUMPRODUCT(MAX(($O22:$Y22<>"")*$AA$3:$AK$3)))} -> 0 | L22: =IF(COUNT($O22:$Y22)=0,"",MAX($O22:$Y22)) | M22: =IF($L22="","",TODAY()-$L22) | N22: =IF($L22="","No Record",IF($K22>=1,"Live",IF($M22>=90,"Stalled 90d+",IF($M22>=60,"Stalled 60d+",IF($M22>=30,"Stalled 30d+","In Progress"))))) -> No Record | Z22: NDA/Contract
A23: =IF($D23="","",COUNTA($D$4:$D23)) -> 20 | B23: =IF($D23="","",IF($L23="","Contact",LOOKUP($K23,$AA$5:$AA$8,$AB$5:$AB$8))) -> Live | C23: Korea | D23: bizplay | E23: Channel API | F23: High | G23: 🟢 Minimal (5-10%) | I23: GSM | J23: Aiden | K23: {=IF($D23="","",SUMPRODUCT(MAX(($O23:$Y23<>"")*$AA$3:$AK$3)))} -> 0.8 | L23: =IF(COUNT($O23:$Y23)=0,"",MAX($O23:$Y23)) -> 46253 | M23: =IF($L23="","",TODAY()-$L23) -> 3 | N23: =IF($L23="","No Record",IF($K23>=1,"Live",IF($M23>=90,"Stalled 90d+",IF($M23>=60,"Stalled 60d+",IF($M23>=30,"Stalled 30d+","In Progress"))))) -> In Progress | V23: 46253 | W23: 46253 | Z23: Contact
A24: =IF($D24="","",COUNTA($D$4:$D24)) -> 21 | B24: =IF($D24="","",IF($L24="","Contact",LOOKUP($K24,$AA$5:$AA$8,$AB$5:$AB$8))) -> Contact | C24: Spain | D24: HBX | E24: Channel API | F24: High | G24: 🔴 Full (100%) | H24: TGX | I24: GSM | J24: Aiden | K24: {=IF($D24="","",SUMPRODUCT(MAX(($O24:$Y24<>"")*$AA$3:$AK$3)))} -> 0 | L24: =IF(COUNT($O24:$Y24)=0,"",MAX($O24:$Y24)) | M24: =IF($L24="","",TODAY()-$L24) | N24: =IF($L24="","No Record",IF($K24>=1,"Live",IF($M24>=90,"Stalled 90d+",IF($M24>=60,"Stalled 60d+",IF($M24>=30,"Stalled 30d+","In Progress"))))) -> No Record | Z24: Contact
A25: =IF($D25="","",COUNTA($D$4:$D25)) -> 22 | B25: =IF($D25="","",IF($L25="","Contact",LOOKUP($K25,$AA$5:$AA$8,$AB$5:$AB$8))) -> Contact | C25: UAE | D25: Webbeds | E25: Channel API | F25: High | G25: 🔴 Full (100%) | I25: GSM | J25: Aiden | K25: {=IF($D25="","",SUMPRODUCT(MAX(($O25:$Y25<>"")*$AA$3:$AK$3)))} -> 0 | L25: =IF(COUNT($O25:$Y25)=0,"",MAX($O25:$Y25)) | M25: =IF($L25="","",TODAY()-$L25) | N25: =IF($L25="","No Record",IF($K25>=1,"Live",IF($M25>=90,"Stalled 90d+",IF($M25>=60,"Stalled 60d+",IF($M25>=30,"Stalled 30d+","In Progress"))))) -> No Record | Z25: Contact
A26: =IF($D26="","",COUNTA($D$4:$D26)) -> 23 | B26: =IF($D26="","",IF($L26="","Contact",LOOKUP($K26,$AA$5:$AA$8,$AB$5:$AB$8))) -> NDA/Contract | C26: Taiwan | D26: Lion Travel | E26: Channel API | F26: High | G26: 🟢 Minimal (5-10%) | H26: SHIJI | I26: GSM | J26: Grace | K26: {=IF($D26="","",SUMPRODUCT(MAX(($O26:$Y26<>"")*$AA$3:$AK$3)))} -> 0.2 | L26: =IF(COUNT($O26:$Y26)=0,"",MAX($O26:$Y26)) -> 45912 | M26: =IF($L26="","",TODAY()-$L26) -> 344 | N26: =IF($L26="","No Record",IF($K26>=1,"Live",IF($M26>=90,"Stalled 90d+",IF($M26>=60,"Stalled 60d+",IF($M26>=30,"Stalled 30d+","In Progress"))))) -> Stalled 90d+ | O26: 45912 | Z26: NDA/Contract
A27: =IF($D27="","",COUNTA($D$4:$D27)) -> 24 | B27: =IF($D27="","",IF($L27="","Contact",LOOKUP($K27,$AA$5:$AA$8,$AB$5:$AB$8))) -> In Development | C27: Taiwan | D27: Star Travel | E27: Channel API | F27: High | G27: 🟢 Minimal (5-10%) | I27: GSM | J27: Grace | K27: {=IF($D27="","",SUMPRODUCT(MAX(($O27:$Y27<>"")*$AA$3:$AK$3)))} -> 0.5 | L27: =IF(COUNT($O27:$Y27)=0,"",MAX($O27:$Y27)) -> 45993 | M27: =IF($L27="","",TODAY()-$L27) -> 263 | N27: =IF($L27="","No Record",IF($K27>=1,"Live",IF($M27>=90,"Stalled 90d+",IF($M27>=60,"Stalled 60d+",IF($M27>=30,"Stalled 30d+","In Progress"))))) -> Stalled 90d+ | P27: 45946 | R27: 45992 | S27: 45993 | Z27: NDA/Contract
A28: =IF($D28="","",COUNTA($D$4:$D28)) -> 25 | B28: =IF($D28="","",IF($L28="","Contact",LOOKUP($K28,$AA$5:$AA$8,$AB$5:$AB$8))) -> In Development | C28: Taiwan | D28: Cola Tour | E28: Channel API | F28: High | G28: 🟢 Minimal (5-10%) | I28: GSM | J28: Grace | K28: {=IF($D28="","",SUMPRODUCT(MAX(($O28:$Y28<>"")*$AA$3:$AK$3)))} -> 0.5 | L28: =IF(COUNT($O28:$Y28)=0,"",MAX($O28:$Y28)) -> 46235 | M28: =IF($L28="","",TODAY()-$L28) -> 21 | N28: =IF($L28="","No Record",IF($K28>=1,"Live",IF($M28>=90,"Stalled 90d+",IF($M28>=60,"Stalled 60d+",IF($M28>=30,"Stalled 30d+","In Progress"))))) -> In Progress | S28: 46235 | Z28: In Development
A29: =IF($D29="","",COUNTA($D$4:$D29)) -> 26 | B29: =IF($D29="","",IF($L29="","Contact",LOOKUP($K29,$AA$5:$AA$8,$AB$5:$AB$8))) -> NDA/Contract | C29: China | D29: Uone | E29: Channel API | G29: 🟢 Minimal (5-10%) | I29: GSM | J29: Grace | K29: {=IF($D29="","",SUMPRODUCT(MAX(($O29:$Y29<>"")*$AA$3:$AK$3)))} -> 0.2 | L29: =IF(COUNT($O29:$Y29)=0,"",MAX($O29:$Y29)) -> 45908 | M29: =IF($L29="","",TODAY()-$L29) -> 348 | N29: =IF($L29="","No Record",IF($K29>=1,"Live",IF($M29>=90,"Stalled 90d+",IF($M29>=60,"Stalled 60d+",IF($M29>=30,"Stalled 30d+","In Progress"))))) -> Stalled 90d+ | O29: 45908 | Z29: Contact
A30: =IF($D30="","",COUNTA($D$4:$D30)) -> 27 | B30: =IF($D30="","",IF($L30="","Contact",LOOKUP($K30,$AA$5:$AA$8,$AB$5:$AB$8))) -> NDA/Contract | C30: China | D30: Amerilink | E30: Channel API | G30: 🟢 Minimal (5-10%) | I30: GSM | J30: Grace | K30: {=IF($D30="","",SUMPRODUCT(MAX(($O30:$Y30<>"")*$AA$3:$AK$3)))} -> 0.2 | L30: =IF(COUNT($O30:$Y30)=0,"",MAX($O30:$Y30)) -> 45957 | M30: =IF($L30="","",TODAY()-$L30) -> 299 | N30: =IF($L30="","No Record",IF($K30>=1,"Live",IF($M30>=90,"Stalled 90d+",IF($M30>=60,"Stalled 60d+",IF($M30>=30,"Stalled 30d+","In Progress"))))) -> Stalled 90d+ | O30: 45957 | Z30: Contact
A31: =IF($D31="","",COUNTA($D$4:$D31)) -> 28 | B31: =IF($D31="","",IF($L31="","Contact",LOOKUP($K31,$AA$5:$AA$8,$AB$5:$AB$8))) -> NDA/Contract | C31: Vietnam | D31: Chudu24 | E31: Channel API | G31: 🟢 Minimal (5-10%) | I31: GSM | J31: Aiden | K31: {=IF($D31="","",SUMPRODUCT(MAX(($O31:$Y31<>"")*$AA$3:$AK$3)))} -> 0.3 | L31: =IF(COUNT($O31:$Y31)=0,"",MAX($O31:$Y31)) -> 46001 | M31: =IF($L31="","",TODAY()-$L31) -> 255 | N31: =IF($L31="","No Record",IF($K31>=1,"Live",IF($M31>=90,"Stalled 90d+",IF($M31>=60,"Stalled 60d+",IF($M31>=30,"Stalled 30d+","In Progress"))))) -> Stalled 90d+ | P31: 46001 | Z31: Contact
A32: =IF($D32="","",COUNTA($D$4:$D32)) -> 29 | B32: =IF($D32="","",IF($L32="","Contact",LOOKUP($K32,$AA$5:$AA$8,$AB$5:$AB$8))) -> Contact | D32: Prime Travel | E32: Channel API | G32: 🟢 Minimal (5-10%) | I32: GSM | J32: Aiden | K32: {=IF($D32="","",SUMPRODUCT(MAX(($O32:$Y32<>"")*$AA$3:$AK$3)))} -> 0 | L32: =IF(COUNT($O32:$Y32)=0,"",MAX($O32:$Y32)) | M32: =IF($L32="","",TODAY()-$L32) | N32: =IF($L32="","No Record",IF($K32>=1,"Live",IF($M32>=90,"Stalled 90d+",IF($M32>=60,"Stalled 60d+",IF($M32>=30,"Stalled 30d+","In Progress"))))) -> No Record | Z32: Contact
A33: =IF($D33="","",COUNTA($D$4:$D33)) -> 30 | B33: =IF($D33="","",IF($L33="","Contact",LOOKUP($K33,$AA$5:$AA$8,$AB$5:$AB$8))) -> In Development | C33: China | D33: Fangcang | E33: Channel API | F33: High | G33: 🟢 Minimal (5-10%) | I33: GSM | J33: Grace | K33: {=IF($D33="","",SUMPRODUCT(MAX(($O33:$Y33<>"")*$AA$3:$AK$3)))} -> 0.5 | L33: =IF(COUNT($O33:$Y33)=0,"",MAX($O33:$Y33)) -> 46246 | M33: =IF($L33="","",TODAY()-$L33) -> 10 | N33: =IF($L33="","No Record",IF($K33>=1,"Live",IF($M33>=90,"Stalled 90d+",IF($M33>=60,"Stalled 60d+",IF($M33>=30,"Stalled 30d+","In Progress"))))) -> In Progress | O33: 46242 | P33: 46243 | Q33: 46244 | R33: 46245 | S33: 46246 | Z33: In Development
A34: =IF($D34="","",COUNTA($D$4:$D34)) -> 31 | B34: =IF($D34="","",IF($L34="","Contact",LOOKUP($K34,$AA$5:$AA$8,$AB$5:$AB$8))) -> Contact | C34: China | D34: Meiya | E34: Channel API | G34: 🟢 Minimal (5-10%) | I34: GSM | J34: IKET | K34: {=IF($D34="","",SUMPRODUCT(MAX(($O34:$Y34<>"")*$AA$3:$AK$3)))} -> 0 | L34: =IF(COUNT($O34:$Y34)=0,"",MAX($O34:$Y34)) | M34: =IF($L34="","",TODAY()-$L34) | N34: =IF($L34="","No Record",IF($K34>=1,"Live",IF($M34>=90,"Stalled 90d+",IF($M34>=60,"Stalled 60d+",IF($M34>=30,"Stalled 30d+","In Progress"))))) -> No Record | Z34: NDA/Contract
A35: =IF($D35="","",COUNTA($D$4:$D35)) -> 32 | B35: =IF($D35="","",IF($L35="","Contact",LOOKUP($K35,$AA$5:$AA$8,$AB$5:$AB$8))) -> In Development | C35: China | D35: JL Tour | E35: Channel API | G35: 🟢 Minimal (5-10%) | I35: GSM | J35: Grace | K35: {=IF($D35="","",SUMPRODUCT(MAX(($O35:$Y35<>"")*$AA$3:$AK$3)))} -> 0.5 | L35: =IF(COUNT($O35:$Y35)=0,"",MAX($O35:$Y35)) -> 45971 | M35: =IF($L35="","",TODAY()-$L35) -> 285 | N35: =IF($L35="","No Record",IF($K35>=1,"Live",IF($M35>=90,"Stalled 90d+",IF($M35>=60,"Stalled 60d+",IF($M35>=30,"Stalled 30d+","In Progress"))))) -> Stalled 90d+ | O35: 45971 | P35: 45971 | Q35: 45971 | R35: 45971 | S35: 45971 | Z35: In Development
A36: =IF($D36="","",COUNTA($D$4:$D36)) -> 33 | B36: =IF($D36="","",IF($L36="","Contact",LOOKUP($K36,$AA$5:$AA$8,$AB$5:$AB$8))) -> Contact | C36: China | D36: Qian Tao | E36: Channel API | G36: 🟢 Minimal (5-10%) | I36: GSM | J36: Grace | K36: {=IF($D36="","",SUMPRODUCT(MAX(($O36:$Y36<>"")*$AA$3:$AK$3)))} -> 0 | L36: =IF(COUNT($O36:$Y36)=0,"",MAX($O36:$Y36)) | M36: =IF($L36="","",TODAY()-$L36) | N36: =IF($L36="","No Record",IF($K36>=1,"Live",IF($M36>=90,"Stalled 90d+",IF($M36>=60,"Stalled 60d+",IF($M36>=30,"Stalled 30d+","In Progress"))))) -> No Record | Z36: NDA/Contract
A37: =IF($D37="","",COUNTA($D$4:$D37)) -> 34 | B37: =IF($D37="","",IF($L37="","Contact",LOOKUP($K37,$AA$5:$AA$8,$AB$5:$AB$8))) -> Contact | C37: India | D37: MakeMyTrip | E37: Channel API | F37: High | G37: 🔴 Full (100%) | I37: GSM | J37: Aiden | K37: {=IF($D37="","",SUMPRODUCT(MAX(($O37:$Y37<>"")*$AA$3:$AK$3)))} -> 0 | L37: =IF(COUNT($O37:$Y37)=0,"",MAX($O37:$Y37)) | M37: =IF($L37="","",TODAY()-$L37) | N37: =IF($L37="","No Record",IF($K37>=1,"Live",IF($M37>=90,"Stalled 90d+",IF($M37>=60,"Stalled 60d+",IF($M37>=30,"Stalled 30d+","In Progress"))))) -> No Record | Z37: NDA/Contract
A38: =IF($D38="","",COUNTA($D$4:$D38)) -> 35 | B38: =IF($D38="","",IF($L38="","Contact",LOOKUP($K38,$AA$5:$AA$8,$AB$5:$AB$8))) -> Contact | C38: Vietnam | D38: Vietravel | E38: Channel API | F38: High | G38: 🟢 Minimal (5-10%) | I38: GSM | J38: Aiden | K38: {=IF($D38="","",SUMPRODUCT(MAX(($O38:$Y38<>"")*$AA$3:$AK$3)))} -> 0 | L38: =IF(COUNT($O38:$Y38)=0,"",MAX($O38:$Y38)) | M38: =IF($L38="","",TODAY()-$L38) | N38: =IF($L38="","No Record",IF($K38>=1,"Live",IF($M38>=90,"Stalled 90d+",IF($M38>=60,"Stalled 60d+",IF($M38>=30,"Stalled 30d+","In Progress"))))) -> No Record | Z38: NDA/Contract
A39: =IF($D39="","",COUNTA($D$4:$D39)) -> 36 | B39: =IF($D39="","",IF($L39="","Contact",LOOKUP($K39,$AA$5:$AA$8,$AB$5:$AB$8))) -> Contact | C39: China | D39: Mafengwo | E39: Channel API | F39: Mid | G39: 🟢 Minimal (5-10%) | I39: GSM | J39: Grace | K39: {=IF($D39="","",SUMPRODUCT(MAX(($O39:$Y39<>"")*$AA$3:$AK$3)))} -> 0 | L39: =IF(COUNT($O39:$Y39)=0,"",MAX($O39:$Y39)) | M39: =IF($L39="","",TODAY()-$L39) | N39: =IF($L39="","No Record",IF($K39>=1,"Live",IF($M39>=90,"Stalled 90d+",IF($M39>=60,"Stalled 60d+",IF($M39>=30,"Stalled 30d+","In Progress"))))) -> No Record | Z39: NDA/Contract
A40: =IF($D40="","",COUNTA($D$4:$D40)) -> 37 | B40: =IF($D40="","",IF($L40="","Contact",LOOKUP($K40,$AA$5:$AA$8,$AB$5:$AB$8))) -> Contact | C40: China | D40: Chai Yi Lc -Yihao | E40: Channel API | F40: High | G40: 🟢 Minimal (5-10%) | I40: GSM | J40: Grace | K40: {=IF($D40="","",SUMPRODUCT(MAX(($O40:$Y40<>"")*$AA$3:$AK$3)))} -> 0 | L40: =IF(COUNT($O40:$Y40)=0,"",MAX($O40:$Y40)) | M40: =IF($L40="","",TODAY()-$L40) | N40: =IF($L40="","No Record",IF($K40>=1,"Live",IF($M40>=90,"Stalled 90d+",IF($M40>=60,"Stalled 60d+",IF($M40>=30,"Stalled 30d+","In Progress"))))) -> No Record | Z40: NDA/Contract
...

Sheet 마진변동 트래킹
A1: 📋 마진 변동 기안서 생성 프롬프트 (Margin Adjustment Proposal Prompt)
A2: 아래 프롬프트를 복사하여 Claude에 붙여넣으면 기안서가 텍스트로 생성됩니다. (Copy the prompt below and paste it into Claude to generate a proposal in text format.)
A3: ▼ 프롬프트 (아래 전체를 복사하세요) / Prompt (Copy everything below)
A4: 아래 정보를 바탕으로 고객사 마진 변동 기안서를 텍스트로 작성해줘. 표 형식 없이, 읽기 쉬운 문서 형태로 출력해줘. (Based on the information below, write a client margin adjustment proposal in text format. Output in a readable document format without tables.) --- [기본 정보 (Basic Info)] - 기안 제목(Title): {제목 입력} - 고객사명(Client): {고객사명 입력} - 담당자(PIC): {담당자명 입력} - 기안일자(Date): {YYYY-MM-DD} - 프로모션명(Promotion): {프로모션명 입력} [마진 변동 내용 (Margin Change Details)] - 기존 마진(Before Markup): {예: 25%} - 변경 마진(After Markup): {예: 22%} - 변동폭(Change): {예: -3%p} - 변동 사유(Reason): {사유 입력} [적용 일정 (Schedule)] - 적용 시작일(Start Date): {YYYY-MM-DD} - 적용 종료일(End Date): {YYYY-MM-DD} - 시작 시간(Start Time): {예: 오전 9시} - 시간대(Timezone): {예: KST / CST} [기대 효과 (Expected Effects)] 1. {기대효과 1} 2. {기대효과 2} 3. {기대효과 3} [결재 (Approval)] - 기안자(Drafter): {성명} - 1차 결재자(1st Approver): {성명} - 최종 결재자(Final Approver): {성명} --- 위 내용으로 "고객사 마진 변동 및 프로모션 진행 건 (Client Margin Adjustment & Promotion)" 형태의 공식 기안서를 작성해줘. 각 섹션에 번호를 매기고, 목적/마진변동내용/적용일정/기대효과/결재란을 포함해줘. 출력은 순수 텍스트(글)로만 해줘.
A5: 📊 마진 변동 트래킹 로그 (Margin Change Tracking Log)
A6: 번호(No.) | B6: 고객사명(Client) | C6: 담당자(PIC) | D6: 프로모션명(Promotion) | E6: 기존 마진(Before) | F6: 변경 마진(After) | G6: 변동폭(Change) | H6: 적용 시작일(Start) | I6: 적용 종료일(End) | J6: 적용 기간(Duration) | K6: 상태(Status) | L6: 결과(Result) | M6: 비고(Note) | N6: Report CEO
A7: 1 | B7: Qiyouji | C7: Grace | D7: OMH PROMOTION | E7: 0.25 | F7: 0.22 | G7: =F7-E7 -> -0.03 | H7: =DATE(2026,3,20) -> 46101 | I7: =DATE(2026,4,3) -> 46115 | J7: =IF(OR(H7="",I7=""),"",I7-H7+1) -> 15 | K7: 진행중(Active) | L7: 소폭 증가 | M7: Aiden Check | N7: ☑
A8: 2 | B8: Dida | C8: Grace | D8: OMH PROMOTION | E8: 0.25 | F8: 0.22 | G8: =F8-E8 -> -0.03 | H8: =DATE(2026,3,27) -> 46108 | I8: 46115 | J8: =IF(OR(H8="",I8=""),"",I8-H8+1) -> 8 | K8: 진행중(Active) | L8: 대폭 증가 | M8: Aiden Check | N8: ☑
A9: 3 | B9: Alitrip | C9: Grace | D9: OMH PROMOTION | E9: 0.25 | F9: 0.22 | G9: -0.03 | H9: =DATE(2026,5,25) -> 46167 | I9: =DATE(2026,6,8) -> 46181 | J9: =IF(OR(H9="",I9=""),"",I9-H9+1) -> 15 | M9: Aiden Check | N9: ☑
A10: 4 | B10: Agoda | C10: Ben | D10: OMH PROMOTION | E10: 0.47 | F10: 0.4 | G10: =IF(OR(E10="",F10=""),"",F10-E10) -> -0.07 | H10: 46175 | I10: 46184 | J10: =IF(OR(H10="",I10=""),"",I10-H10+1) -> 10 | K10: 진행중(Active) | M10: Aiden Check | N10: ☑
G11: =IF(OR(E11="",F11=""),"",F11-E11) | J11: =IF(OR(H11="",I11=""),"",I11-H11+1)
G12: =IF(OR(E12="",F12=""),"",F12-E12) | J12: =IF(OR(H12="",I12=""),"",I12-H12+1)
G13: =IF(OR(E13="",F13=""),"",F13-E13) | J13: =IF(OR(H13="",I13=""),"",I13-H13+1)
G14: =IF(OR(E14="",F14=""),"",F14-E14) | J14: =IF(OR(H14="",I14=""),"",I14-H14+1)
G15: =IF(OR(E15="",F15=""),"",F15-E15) | J15: =IF(OR(H15="",I15=""),"",I15-H15+1)
G16: =IF(OR(E16="",F16=""),"",F16-E16) | J16: =IF(OR(H16="",I16=""),"",I16-H16+1)
G17: =IF(OR(E17="",F17=""),"",F17-E17) | J17: =IF(OR(H17="",I17=""),"",I17-H17+1)
G18: =IF(OR(E18="",F18=""),"",F18-E18) | J18: =IF(OR(H18="",I18=""),"",I18-H18+1)
G19: =IF(OR(E19="",F19=""),"",F19-E19) | J19: =IF(OR(H19="",I19=""),"",I19-H19+1)
G20: =IF(OR(E20="",F20=""),"",F20-E20) | J20: =IF(OR(H20="",I20=""),"",I20-H20+1)
G21: =IF(OR(E21="",F21=""),"",F21-E21) | J21: =IF(OR(H21="",I21=""),"",I21-H21+1)
G22: =IF(OR(E22="",F22=""),"",F22-E22) | J22: =IF(OR(H22="",I22=""),"",I22-H22+1)
... G28: =IF(OR(E28="",F28=""),"",F28-E28) | J28: =IF(OR(H28="",I28=""),"",I28-H28+1)

Sheet 계약변경
A1: No. | B1: Company | C1: Settlement Period | D1: Contract Date | E1: Follow Up | F1: 완료 날짜(예상포함) | G1: Citibank announcement
A2: 1 | B2: MEITUAN | C2: Weekly | D2: 46083 | E2: 3/2 재변경 진행 중 | F2: 46143 | G2: 화폐 모두 변경 완료 | H2: 이전 check out 건 manual 정리 포함
A3: 2 | B3: QUNAR | C3: Weekly | E3: 4/6 변경 진행 중 | F3: 46174 | G3: 6/1 변경 완료 | H3: Qunar 6/3일 내부 변경 예정, 원본 합의서 우편으로 보냄
A4: 3 | B4: CONVERGENT | C4: Weekly | D4: 46083 | E4: 3/2 재변경 완료 | F4: 46125 | G4: 4/13변경 완료
A5: 4 | B5: TONGCHENG | C5: Weekly | D5: 46083 | E5: 3/2 변경 완료 | F5: 46104 | G5: 3/23 변경 완료
A6: 5 | B6: Traveloka | C6: Monthly | E6: 6/4 change completely | F6: 46143 | G6: 6/4 finish
A7: 6 | B7: PKFARE | C7: Bi-Weekly | D7: 46097 | E7: 3/16 변경 완료 - 이건 한국 들어감 | F7: 46113 | G7: 4/1변경 완료
A8: 7 | B8: QIYOUJI | C8: Bi-Weekly | D8: 46097 | E8: 3/16 변경 완료 | F8: 46113 | G8: 4/1변경 완료
A9: 8 | B9: DIDA | C9: Bi-Weekly | D9: 46113 | E9: 4/1 재변경 진행 중 | F9: 46143 | G9: 4/16 변경 완료
A10: 9 | B10: TOURMIND | C10: Bi-Weekly | D10: 46097 | E10: 4/1 재변경 진행 중 | F10: 46113 | G10: 4/1변경 완료
A11: 10 | B11: HEYTRIP | C11: Bi-Weekly | D11: 46143 | E11: 4/1 협의 진행 중, 데포짓 변경처리 필요 | F11: 46143 | G11: 5/1로 변경 완료 | H11: deposit 우리에게 씨티 입금해야되는데, Heytrip 담당 입금정보 시스템에서 업데이트 안되어있어 싱가포르 KEB Hana 엔화 계좌 입금했음
A12: 11 | B12: KAKE | C12: Bi-Weekly | D12: 46113 | E12: 리뷰 회신 대기 중 -3/16계약로 진행 | F12: 46113 | G12: 4/1변경 완료
A13: 12 | B13: ALITRIP | C13: Bi-Weekly | D13: 46082 | E13: 3/1 재변경 완료 | F13: 46113 | G13: 4/1변경 완료
A14: 13 | B14: SS BOOKING | C14: Bi-Weekly | D14: 46097 | E14: 3/16 변경 완료 | F14: 46097 | G14: 3/16 변경 완료
A15: 14 | B15: TOPTOWN | C15: Bi-Weekly | D15: 46082 | E15: 3/1 재변경 완료 | F15: 46113 | G15: 4/1변경 완료
A16: 15 | B16: RTX | C16: Bi-Weekly | D16: 46082 | E16: 4/1 변경 완료 | F16: 46113 | G16: 변경 완료
A17: 16 | B17: Room Deal (MG) | C17: Bi-Weekly | D17: 46097 | E17: 5/1자 변경 진행 중, 크로스셀링으로 진행 | F17: 46188 | G17: MS. Sophia review the MG's feedback - related to Purchasing contract
A18: 17 | B18: Ctrip | C18: Weekly | D18: 46143 | F18: 46143 | G18: 메일 확인 ~ 소피아님 확인 필요
A19: 18 | B19: Agoda
A21: No. | B21: Company | C21: Settlement Period | D21: Contract Date | E21: Follow Up | F21: 완료 날짜(예상포함) | G21: Citibank announcement
A22: 1 | B22: HOTELBANK | C22: Bi-Weekly | D22: 46082 | E22: 3/1 재변경 완료 | F22: 46113 | G22: 4/1변경 완료
A23: 2 | B23: HUAMIN | C23: Bi-Weekly | D23: 46097 | E23: 3/16변경 완료 | F23: 46113 | G23: 4/1변경 완료
A24: 3 | B24: COOLPRICE | C24: Bi-Weekly | D24: 46082 | E24: 3/31 Addendum 보냈음 | F24: 46113 | G24: 4/1변경 완료
A25: 4 | B25: STAR TRAVEL | C25: Bi-Weekly | D25: 46082 | E25: addendum with new bank acc | F25: 46113 | G25: 4/1변경 완료 ( no addendum yet)
A26: 5 | B26: LINKSTAY | C26: Bi-Weekly | D26: 46082 | E26: 3/31 Addendum 보냈음 | F26: 46113 | G26: 4/1변경 완료
A27: 6 | B27: KLOOK | C27: Bi-Weekly | D27: 46082 | E27: New contract | F27: 46113 | G27: 4/1변경 완료
A28: 7 | B28: JL Tour | C28: Bi-Weekly | F28: 46113 | G28: 4/1변경 완료
A29: 8 | B29: Bingtrip | C29: Weekly | F29: 46113 | G29: 4/1변경 완료

Sheet Mapping Schedule
A1: [2026 Mapping Schedule] | J1: Q1 | W1: Q2 | AJ1: Q3 | AW1: Q4
J2: Jan | N2: Feb | R2: Mar | W2: Apr | AA2: May | AE2: Jun | AJ2: Jul | AN2: Aug | AS2: Sep | AW2: Oct | BA2: Nov | BF2: Dec
